Workbook

Sheet Acoustic_parameters3_1
A1: Subject | B1: RR_TSK2 | C1: IPAmean_TSK2 | D1: MPT_TSK6 | E1: HNR_TSK3 | F1: HNR_TSK4 | G1: HNR_TSK5 | H1: HNR_TSK6 | I1: HRF_TSK3 | J1: HRF_TSK4 | K1: HRF_TSK5 | L1: HRF_TSK6 | M1: Jitter_TSK3 | N1: Jitter_TSK4 | O1: Jitter_TSK5 | P1: Jitter_TSK6 | Q1: Shimmer_TSK3 | R1: Shimmer_TSK4 | S1: Shimmer_TSK5 | T1: Shimmer_TSK6 | U1: PPQ_TSK3 | V1: PPQ_TSK4 | W1: PPQ_TSK5 | X1: PPQ_TSK6 | Y1: APQ_TSK3 | Z1: APQ_TSK4 | AA1: APQ_TSK5 | AB1: APQ_TSK6 | AC1: DF0_TSK3 | AD1: DF0_TSK4 | AE1: DF0_TSK5 | AF1: DF0_TSK6 | AG1: DDF0_TSK3 | AH1: DDF0_TSK4 | AI1: DDF0_TSK5 | AJ1: DDF0_TSK6 | AK1: DUV_TSK3 | AL1: DUV_TSK4 | AM1: DUV_TSK5 | AN1: DUV_TSK6 | AO1: RelF1SD_TSK1 | AP1: RelF1SD_TSK2 | AQ1: RelF1SD_TSK3 | AR1: RelF1SD_TSK4 | AS1: RelF1SD_TSK5 | AT1: RelF1SD_TSK6 | AU1: RelF2SD_TSK1 | AV1: RelF2SD_TSK2 | AW1: RelF2SD_TSK3 | AX1: RelF2SD_TSK4 | AY1: RelF2SD_TSK5 | AZ1: RelF2SD_TSK6 | BA1: VAI_TSK1 | BB1: VSHA_TSK1 | BC1: AAVS_TSK1 | BD1: VAI_TSK2 | BE1: VSHA_TSK2 | BF1: AAVS_TSK2 | BG1: PR_TSK7 | BH1: COV_TSK7 | BI1: PA_TSK7 | BJ1: RI_TSK7 | BK1: RA_TSK7 | BL1: RelF0SD_TSK1 | BM1: RelF0SD_TSK2 | BN1: RelSE0SD_TSK1 | BO1: RelSE0SD_TSK2 | BP1: DurMED_TSK1 | BQ1: DurMAD_TSK1 | BR1: SPIR_TSK1 | BS1: pause_n_TSK1 | BT1: pause_ratio_TSK1 | BU1: DurMED_TSK2 | BV1: DurMAD_TSK2 | BW1: SPIR_TSK2 | BX1: pause_n_TSK2 | BY1: pause_ratio_TSK2
A2: COBEN_CZCOBEN000 | B2: 25.073686 | C2: 0.57241379 | D2: 6.191 | E2: 20.707322 | F2: 26.453432 | G2: 15.707774 | H2: 17.783313 | I2: 0.11183252 | J2: 0.0025160773 | K2: 0.0048214806 | L2: 0.28617144 | M2: 0.56947139 | N2: 0.4985867 | O2: 0.80357554 | P2: 0.974236 | Q2: 2.9755428 | R2: 1.4656941 | S2: 5.4686503 | T2: 1.6988423 | U2: 0.0023426134 | V2: 0.0016967899 | W2: 0.0031494808 | X2: 0.0036659139 | Y2: 0.020466571 | Z2: 0.016685846 | AA2: 0.13685297 | AB2: 0.026908778 | AC2: -1.3652802 | AD2: 0.026550293 | AE2: -1.5717621 | AF2: -1.409317 | AG2: -1.7141266 | AH2: 1.7331696 | AI2: -3.7300873 | AJ2: -1.1151276 | AK2: 0 | AL2: 0 | AM2: 0 | AN2: 7.143 | AO2: 0.62327467 | AP2: 0.65569872 | AQ2: 0.49102094 | AR2: 0.017407059 | AS2: 0.16290869 | AT2: 0.39673081 | AU2: 0.28308772 | AV2: 0.31028616 | AW2: 0.37894718 | AX2: 0.10378411 | AY2: 0.41293575 | AZ2: 0.29728417 | BA2: 1.1152687 | BB2: 270745.6 | BC2: 45484.518 | BD2: 1.1224973 | BE2: 248250.18 | BF2: 47784.091 | BG2: =MEDIAN!BG3 -> 5.2301357 | BH2: =MEDIAN!BH3 -> 6.1937647 | BI2: =MEDIAN!BI3 -> 3.6700337 | BJ2: 0.037020316 | BK2: -0.0096 | BL2: 0.1534223 | BM2: 0.17929899 | BN2: 0.14311987 | BO2: 0.20133271 | BP2: 0.604 | BQ2: 0.152 | BR2: 2.2195319 | BS2: 30 | BT2: 23.719128 | BU2: 0.608 | BV2: 0.176 | BW2: 2.579698 | BX2: 33 | BY2: 22.401692
A3: COBEN_CZCOBEN002 | B3: 21.391963 | C3: 0.4555 | D3: 26.810063 | E3: 23.034499 | F3: 26.096321 | G3: 26.217874 | H3: 21.19677 | I3: 2.0165309 | J3: =MEDIAN!J3 -> 0.012911715 | K3: =MEDIAN!K3 -> 0.019033999 | L3: 1.4057066 | M3: 0.46469014 | N3: =MEDIAN!N3 -> 0.45980973 | O3: =MEDIAN!O3 -> 0.47728057 | P3: 0.60663404 | Q3: 2.1164417 | R3: =MEDIAN!R3 -> 2.1672251 | S3: =MEDIAN!S3 -> 3.0238903 | T3: 2.722125 | U3: 0.0016615001 | V3: =MEDIAN!V3 -> 0.0017585262 | W3: =MEDIAN!W3 -> 0.0017543883 | X3: 0.00244914 | Y3: 0.019930908 | Z3: =MEDIAN!Z3 -> 0.019569346 | AA3: =MEDIAN!AA3 -> 0.035706798 | AB3: 0.035974154 | AC3: -1.2923431 | AD3: =MEDIAN!AD3 -> 0.029075623 | AE3: =MEDIAN!AE3 -> -0.058403015 | AF3: -1.3835449 | AG3: -1.3348541 | AH3: =MEDIAN!AH3 -> -0.014801025 | AI3: =MEDIAN!AI3 -> -0.0080337524 | AJ3: 1.4519196 | AK3: 0 | AL3: =MEDIAN!AL3 -> 0 | AM3: =MEDIAN!AM3 -> 0 | AN3: 0 | AO3: 0.72691313 | AP3: 0.67810856 | AQ3: 0.15137319 | AR3: =MEDIAN!AR3 -> 0.022645571 | AS3: =MEDIAN!AS3 -> 0.047530605 | AT3: 0.20577629 | AU3: 0.27993821 | AV3: 0.27507601 | AW3: 0.38474079 | AX3: =MEDIAN!AX3 -> 0.015675058 | AY3: =MEDIAN!AY3 -> 0.083154555 | AZ3: 0.51389231 | BA3: 0.95376728 | BB3: 121167.37 | BC3: 25089.263 | BD3: 0.98849579 | BE3: 230485.69 | BF3: 40506.545 | BG3: 4.7348485 | BH3: 19.233126 | BI3: 18.518519 | BJ3: 0.085914086 | BK3: 0.0077575758 | BL3: 0.10927424 | BM3: 0.25684005 | BN3: 0.11886093 | BO3: 0.17347781 | BP3: 0.492 | BQ3: 0.084 | BR3: 2.4245264 | BS3: 20 | BT3: 8.6886824 | BU3: 0.52 | BV3: 0.1 | BW3: 2.6829017 | BX3: 24 | BY3: 15.167496
A4: COBEN_CZCOBEN004 | B4: 9.2871979 | C4: 0.57714286 | D4: 12.245062 | E4: 16.075013 | F4: 19.695853 | G4: 20.192355 | H4: 15.407464 | I4: 0.94251893 | J4: 0.025410034 | K4: 0.10571888 | L4: 1.8712088 | M4: 0.53413503 | N4: 0.44248264 | O4: 0.53925959 | P4: 0.90773795 | Q4: 3.7226203 | R4: 4.3935139 | S4: 3.8040734 | T4: 2.3543986 | U4: 0.0030773228 | V4: 0.0030763996 | W4: 0.0031118374 | X4: 0.0036713284 | Y4: 0.048847221 | Z4: 0.057393856 | AA4: 0.061639515 | AB4: 0.07025976 | AC4: 0.34939575 | AD4: -0.1519165 | AE4: -1.6257477 | AF4: -1.34758 | AG4: -0.25411987 | AH4: 2.1128845 | AI4: -1.1300354 | AJ4: -0.29048157 | AK4: 0 | AL4: 0 | AM4: 0 | AN4: 0.082 | AO4: 0.51808586 | AP4: 0.57368626 | AQ4: 0.085000931 | AR4: 0.012327162 | AS4: 0.1852474 | AT4: 0.1522803 | AU4: 0.25056338 | AV4: 0.26135759 | AW4: 0.038792504 | AX4: 0.0090541417 | AY4: 0.36690703 | AZ4: 0.051593127 | BA4: 0.92187028 | BB4: 508457.24 | BC4: 74275.982 | BD4: 1.0523235 | BE4: 474567.64 | BF4: 74671.05 | BG4: 4.5955882 | BH4: 4.5946829 | BI4: 3.3333333 | BJ4: 0.033538332 | BK4: -0.0064904348 | BL4: 0.13298555 | BM4: 0.15989037 | BN4: 0.10336562 | BO4: 0.15090139 | BP4: 0.664 | BQ4: 0.128 | BR4: 2.1281979 | BS4: 11 | BT4: 4.5395808 | BU4: 0.584 | BV4: 0.088 | BW4: 2.1378323 | BX4: 10 | BY4: 7.491673
A5: COBEN_CZCOBEN005 | B5: 2.5461467 | C5: 0.41 | D5: 9.2325625 | E5: 15.173455 | F5: 29.891774 | G5: 34.464193 | H5: 15.513153 | I5: 1.1451854 | J5: 0.013722188 | K5: 0.11550986 | L5: 1.4245916 | M5: 0.44082806 | N5: 0.19150222 | O5: 0.17899461 | P5: 0.63702868 | Q5: 4.597187 | R5: 3.123156 | S5: 1.8567317 | T5: 2.6574884 | U5: 0.0024586157 | V5: 0.00068428981 | W5: 0.00093049112 | X5: 0.0025065009 | Y5: 0.034350466 | Z5: 0.016551201 | AA5: 0.010460184 | AB5: 0.039480249 | AC5: 0.87791443 | AD5: 0.80990601 | AE5: -0.48245239 | AF5: -0.83755493 | AG5: 2.151535 | AH5: 0.99868774 | AI5: 0.71682739 | AJ5: -1.7651672 | AK5: 0 | AL5: 0 | AM5: 0 | AN5: 0.217 | AO5: 0.55490904 | AP5: 0.57230408 | AQ5: 0.065361676 | AR5: 0.020006283 | AS5: 0.084898639 | AT5: 0.058721968 | AU5: 0.2240953 | AV5: 0.23909457 | AW5: 0.03139136 | AX5: 0.24042261 | AY5: 0.15685429 | AZ5: 0.087049503 | BA5: 1.0135864 | BB5: 793189.81 | BC5: 99862.285 | BD5: 0.97247303 | BE5: 597780.99 | BF5: 57145.512 | BG5: =MEDIAN!BG3 -> 5.2301357 | BH5: =MEDIAN!BH3 -> 6.1937647 | BI5: =MEDIAN!BI3 -> 3.6700337 | BJ5: 0.022106361 | BK5: 0.018285714 | BL5: 0.22881592 | BM5: 0.1996958 | BN5: 0.072849307 | BO5: 0.11565532 | BP5: 0.488 | BQ5: 0.184 | BR5: 2.0829172 | BS5: 2 | BT5: 0.79799882 | BU5: 0.664 | BV5: 0.144 | BW5: 2.6945062 | BX5: 3 | BY5: 1.5559785
A6: COBEN_CZCOBEN007 | B6: 13.848802 | C6: 0.63384615 | D6: 13.640063 | E6: 21.599776 | F6: 29.834193 | G6: 11.284619 | H6: 22.666911 | I6: 0.10519124 | J6: 0.0022400806 | K6: 0.0022567335 | L6: 0.11637594 | M6: 0.80200954 | N6: 0.70331369 | O6: 1.3144844 | P6: 0.7937388 | Q6: 3.4741094 | R6: 2.2651529 | S6: 8.1812718 | T6: 2.9404664 | U6: 0.0045444883 | V6: 0.0015523263 | W6: 0.0059685347 | X6: 0.0040946906 | Y6: 0.044403848 | Z6: 0.021231361 | AA6: 0.21040138 | AB6: 0.048717386 | AC6: -0.8698349 | AD6: 1.3788452 | AE6: -2.3986969 | AF6: 1.5680313 | AG6: 0.29632568 | AH6: -0.027801514 | AI6: -5.4428711 | AJ6: -1.6452789 | AK6: 0 | AL6: 0 | AM6: 0 | AN6: 0 | AO6: 0.72351933 | AP6: 0.7032938 | AQ6: 0.1989091 | AR6: 0.014067812 | AS6: 0.61636963 | AT6: 0.31469315 | AU6: 0.30345732 | AV6: 0.31548607 | AW6: 0.13888897 | AX6: 0.016479331 | AY6: 0.18486205 | AZ6: 0.29917678 | BA6: 0.9990876 | BB6: 167390.25 | BC6: 26968.052 | BD6: 1.0602227 | BE6: 204661.41 | BF6: 36274.63 | BG6: 5.1089918 | BH6: 46.905715 | BI6: 9.4594595 | BJ6: 0.14504689 | BK6: -0.015983488 | BL6: 0.13737743 | BM6: 0.16400777 | BN6: 0.10261243 | BO6: 0.16639159 | BP6: 0.564 | BQ6: 0.108 | BR6: 1.5729873 | BS6: 31 | BT6: 15.207639 | BU6: 0.6 | BV6: 0.136 | BW6: 1.1882725 | BX6: 13 | BY6: 14.630016
A7: COBEN_CZCOBEN008 | B7: 18.654102 | C7: 0.433125 | D7: 19.742562 | E7: 26.202009 | F7: 25.633564 | G7: 29.605758 | H7: 24.731596 | I7: 1.2649911 | J7: 0.007382745 | K7: 0.0029365523 | L7: 1.7437169 | M7: 0.36564134 | N7: 0.45677757 | O7: 0.32747418 | P7: 0.52593032 | Q7: 2.8442391 | R7: 2.8984346 | S7: 2.5175117 | T7: 1.4826261 | U7: 0.0012459262 | V7: 0.0021740124 | W7: 0.0020805531 | X7: 0.0019890897 | Y7: 0.021272895 | Z7: 0.025870778 | AA7: 0.017883496 | AB7: 0.024379803 | AC7: -1.0361023 | AD7: 1.5920868 | AE7: 0.82556152 | AF7: -0.22369385 | AG7: -0.75505066 | AH7: 1.1490173 | AI7: -0.71220398 | AJ7: -0.72845459 | AK7: 0 | AL7: 0 | AM7: 0 | AN7: 0.101 | AO7: 0.65866384 | AP7: 0.64058619 | AQ7: 0.044469704 | AR7: 0.023635697 | AS7: 0.081110838 | AT7: 0.062363426 | AU7: 0.2588285 | AV7: 0.27262082 | AW7: 0.013661026 | AX7: 0.013605426 | AY7: 0.1711718 | AZ7: 0.023957623 | BA7: 0.96457941 | BB7: 234729.99 | BC7: 38551.445 | BD7: 0.99638489 | BE7: 308135.98 | BF7: 52349.787 | BG7: 6.7204301 | BH7: 5.6261423 | BI7: 4.0816327 | BJ7: 0.046790651 | BK7: -0.0005374861 | BL7: 0.12956923 | BM7: 0.21268421 | BN7: 0.16591968 | BO7: 0.17903286 | BP7: 0.48 | BQ7: 0.128 | BR7: 1.7887323 | BS7: 26 | BT7: 12.582326 | BU7: 0.536 | BV7: 0.128 | BW7: 2.1822502 | BX7: 19 | BY7: 12.681517
A8: COBEN_CZCOBEN009 | B8: 20.327703 | C8: 0.5336 | D8: 20.787562 | E8: 20.363663 | F8: 27.896578 | G8: 34.866696 | H8: 26.7639 | I8: 0.71080246 | J8: 0.14057288 | K8: 0.34428077 | L8: 1.1620895 | M8: 1.4793441 | N8: 0.22069173 | O8: 0.22265527 | P8: 0.6927759 | Q8: 3.3412257 | R8: 2.517614 | S8: 1.867766 | T8: 1.4152247 | U8: 0.0020643628 | V8: 0.00070231017 | W8: 0.001309032 | X8: 0.0013289469 | Y8: 0.029475086 | Z8: 0.013768522 | AA8: 0.0089771464 | AB8: 0.019591371 | AC8: 1.3616333 | AD8: 0.75086975 | AE8: -1.1304932 | AF8: -0.21696472 | AG8: 1.61586 | AH8: 0.062286377 | AI8: -1.1053162 | AJ8: -2.2592163 | AK8: 0 | AL8: 0 | AM8: 0 | AN8: 0.096 | AO8: 0.59809267 | AP8: 0.58642949 | AQ8: 0.064720355 | AR8: 0.01312346 | AS8: 0.020709126 | AT8: 0.096488839 | AU8: 0.31503637 | AV8: 0.32859653 | AW8: 0.039458903 | AX8: 0.011968164 | AY8: 0.018474287 | AZ8: 0.06611338 | BA8: 1.2003559 | BB8: 503145.51 | BC8: 91826.081 | BD8: 1.1662848 | BE8: 510473.49 | BF8: 93099.441 | BG8: 5.6818182 | BH8: 9.19254 | BI8: -10.638298 | BJ8: 0.057593169 | BK8: 0.00047863248 | BL8: 0.14803891 | BM8: 0.18482861 | BN8: 0.071039262 | BO8: 0.086898185 | BP8: 0.576 | BQ8: 0.216 | BR8: 2.5289021 | BS8: 19 | BT8: 10.222227 | BU8: 0.728 | BV8: 0.176 | BW8: 2.3461346 | BX8: 26 | BY8: 17.708556
A9: COBEN_CZCOBEN010 | B9: 23.607501 | C9: 0.66208333 | D9: 9.2200625 | E9: 23.956093 | F9: 25.505452 | G9: 18.267055 | H9: 23.371574 | I9: 0.58844518 | J9: 0.062598539 | K9: 0.012570393 | L9: 0.79372137 | M9: 0.43398116 | N9: 0.49952187 | O9: 0.5366634 | P9: 0.59048947 | Q9: 1.4648847 | R9: 1.5740484 | S9: 5.33139 | T9: 1.4138249 | U9: 0.00164948 | V9: 0.0013964613 | W9: 0.0013406951 | X9: 0.0018019475 | Y9: 0.016114849 | Z9: 0.011044542 | AA9: 0.12708115 | AB9: 0.016747709 | AC9: 1.3145142 | AD9: -1.7164307 | AE9: -1.0370331 | AF9: -1.666275 | AG9: 1.6677551 | AH9: -0.99838257 | AI9: 1.8466797 | AJ9: -0.78024292 | AK9: 0 | AL9: 0 | AM9: 0 | AN9: 0 | AO9: 0.62122296 | AP9: 0.60507163 | AQ9: 0.040681871 | AR9: 0.063780174 | AS9: 0.036587076 | AT9: 0.056830873 | AU9: 0.26279092 | AV9: 0.26343384 | AW9: 0.033395061 | AX9: 0.085266173 | AY9: 0.023884657 | AZ9: 0.04289632 | BA9: 0.94548078 | BB9: 136663.7 | BC9: 28136.226 | BD9: 0.99643889 | BE9: 182845.05 | BF9: 30583.172 | BG9: 4.8828125 | BH9: 8.3625339 | BI9: -2.8571429 | BJ9: 0.069144919 | BK9: -0.009372549 | BL9: 0.19557517 | BM9: 0.21079422 | BN9: 0.13821362 | BO9: 0.16916503 | BP9: 0.628 | BQ9: 0.2 | BR9: 2.4021624 | BS9: 29 | BT9: 19.234711 | BU9: 0.668 | BV9: 0.196 | BW9: 2.6809235 | BX9: 24 | BY9: 26.050221
A10: COBEN_CZCOBEN011 | B10: 14.883398 | C10: 0.58583333 | D10: 7.9150625 | E10: 18.728939 | F10: 24.17288 | G10: 32.521721 | H10: 18.21033 | I10: 7.7269588 | J10: 0.013951362 | K10: 0.019087007 | L10: 8.1029633 | M10: 0.48358781 | N10: 0.63565904 | O10: 0.47400611 | P10: 0.53870612 | Q10: 1.8778943 | R10: 2.6144109 | S10: 2.8968633 | T10: 1.4486861 | U10: 0.0031231329 | V10: 0.0023659658 | W10: 0.0014235422 | X10: 0.0030015726 | Y10: 0.023386643 | Z10: 0.02333274 | AA10: 0.013481288 | AB10: 0.025670666 | AC10: 0.48040771 | AD10: -0.80728149 | AE10: 0.71289062 | AF10: -0.40306091 | AG10: 1.3705444 | AH10: -1.9948425 | AI10: -0.30076599 | AJ10: 0.099746704 | AK10: 0 | AL10: 0 | AM10: 0 | AN10: 0 | AO10: 0.63348463 | AP10: 0.65093067 | AQ10: 0.018955629 | AR10: 0.046059012 | AS10: 0.0066216635 | AT10: 0.026323043 | AU10: 0.25688452 | AV10: 0.26165141 | AW10: 0.0041129941 | AX10: 0.055942877 | AY10: 0.018311337 | AZ10: 0.014063018 | BA10: 0.88147716 | BB10: 244409.24 | BC10: 33297.543 | BD10: 0.95422905 | BE10: 204524.34 | BF10: 39586.032 | BG10: 5.859375 | BH10: 7.1692634 | BI10: 7.1428571 | BJ10: 0.04560256 | BK10: 0.00096703297 | BL10: 0.26776644 | BM10: 0.19357342 | BN10: 0.056726451 | BO10: 0.1278184 | BP10: 0.544 | BQ10: 0.248 | BR10: 2.8617394 | BS10: 19 | BT10: 10.219605 | BU10: 0.5 | BV10: 0.108 | BW10: 2.3894244 | BX10: 15 | BY10: 12.898945
A11: COBEN_CZCOBEN012 | B11: 17.375553 | C11: 0.47125 | D11: 26.335062 | E11: 18.927643 | F11: 26.658769 | G11: 22.767086 | H11: 17.610419 | I11: 0.75892271 | J11: 0.017412926 | K11: 0.028913283 | L11: 1.3890517 | M11: 0.62051962 | N11: 0.49291702 | O11: 0.36705478 | P11: 0.67661706 | Q11: 3.2617482 | R11: 2.0596396 | S11: 3.7115687 | T11: 0.99192477 | U11: 0.0034279027 | V11: 0.0022380914 | W11: 0.0012350146 | X11: 0.0046589169 | Y11: 0.032465039 | Z11: 0.021866144 | AA11: 0.070582307 | AB11: 0.031204174 | AC11: -1.1427002 | AD11: 0.47219086 | AE11: 0.35728455 | AF11: -1.155014 | AG11: 0.16853333 | AH11: 1.0473251 | AI11: 0.63551331 | AJ11: 0.07950592 | AK11: 0 | AL11: 0 | AM11: 0 | AN11: 0.38 | AO11: 0.75509623 | AP11: 0.66567249 | AQ11: 0.028364785 | AR11: 0.01637102 | AS11: 0.0083885256 | AT11: 0.064748678 | AU11: 0.33539412 | AV11: 0.34055652 | AW11: 0.016312926 | AX11: 0.0036257156 | AY11: 0.0060342514 | AZ11: 0.022515059 | BA11: 1.0588248 | BB11: 302976.82 | BC11: 57617.956 | BD11: 1.1387973 | BE11: 322229.33 | BF11: 65264.017 | BG11: =MEDIAN!BG$3 -> 5.2301357 | BH11: =MEDIAN!BH$3 -> 6.1937647 | BI11: =MEDIAN!BI$3 -> 3.6700337 | BJ11: 0.062295082 | BK11: -0.0592 | BL11: 0.1076814 | BM11: 0.16176542 | BN11: 0.084118368 | BO11: 0.13735055 | BP11: 0.432 | BQ11: 0.064 | BR11: 1.7346271 | BS11: 14 | BT11: 5.2800796 | BU11: 0.44 | BV11: 0.096 | BW11: 2.1072085 | BX11: 24 | BY11: 11.692299
A12: COBEN_CZCOBEN013 | B12: 14.875212 | C12: 0.63941176 | D12: 17.595063 | E12: 20.124961 | F12: 25.395051 | G12: 31.894542 | H12: 19.051577 | I12: 0.38084348 | J12: 0.015711329 | K12: 0.010513121 | L12: 0.7198606 | M12: 0.52878895 | N12: 0.39012244 | O12: 0.40105883 | P12: 1.4253688 | Q12: 2.9952371 | R12: 2.1965555 | S12: 2.3016813 | T12: 2.6321272 | U12: 0.0026379479 | V12: 0.001884384 | W12: 0.0017522518 | X12: 0.0035431402 | Y12: 0.025826946 | Z12: 0.0129138 | AA12: 0.012249462 | AB12: 0.034668062 | AC12: 1.2002563 | AD12: -1.6475677 | AE12: -1.2266083 | AF12: -3.2288818 | AG12: 2.4793396 | AH12: -3.4676056 | AI12: -0.36390686 | AJ12: -1.3898163 | AK12: 0 | AL12: 0 | AM12: 0 | AN12: 0 | AO12: 0.58058517 | AP12: 0.59016931 | AQ12: 0.067602087 | AR12: 0.022599088 | AS12: 0.10064214 | AT12: 0.095150788 | AU12: 0.28466182 | AV12: 0.31036296 | AW12: 0.056090532 | AX12: 0.0059913255 | AY12: 0.36928583 | AZ12: 0.050992966 | BA12: 1.1443167 | BB12: 462529.72 | BC12: 89428.565 | BD12: 1.0954583 | BE12: 338257.71 | BF12: 65690.813 | BG12: 4.3808411 | BH12: 8.1213673 | BI12: -3.0769231 | BJ12: 0.034921739 | BK12: -0.0040123077 | BL12: 0.2255031 | BM12: 0.20514248 | BN12: 0.13042136 | BO12: 0.22408438 | BP12: 0.528 | BQ12: 0.176 | BR12: 2.0926119 | BS12: 25 | BT12: 13.574307 | BU12: 0.552 | BV12: 0.184 | BW12: 2.0679031 | BX12: 19 | BY12: 14.888261
A13: COBEN_CZCOBEN014 | B13: 21.629542 | C13: 0.57230769 | D13: 19.570062 | E13: 24.390054 | F13: 30.78432 | G13: 33.552713 | H13: 25.026308 | I13: 1.4433108 | J13: 0.010482413 | K13: 0.026457045 | L13: 2.3390147 | M13: 0.3635152 | N13: 0.33768992 | O13: 0.3422931 | P13: 0.37484923 | Q13: 3.3997766 | R13: 2.1886008 | S13: 1.9534587 | T13: 0.74213222 | U13: 0.0013594429 | V13: 0.0011295695 | W13: 0.0012060507 | X13: 0.0015096178 | Y13: 0.020331861 | Z13: 0.01181832 | AA13: 0.011530557 | AB13: 0.023568539 | AC13: 0.85749817 | AD13: -1.0931702 | AE13: 0.83340454 | AF13: -2.3190613 | AG13: 0.92951965 | AH13: -2.6520996 | AI13: 1.1868134 | AJ13: -0.85185242 | AK13: 0 | AL13: 0 | AM13: 0 | AN13: 0.051 | AO13: 0.57146272 | AP13: 0.51851391 | AQ13: 0.015293113 | AR13: 0.015514631 | AS13: 0.015756223 | AT13: 0.043044096 | AU13: 0.2601695 | AV13: 0.26668939 | AW13: 0.0090732835 | AX13: 0.14892232 | AY13: 0.055528514 | AZ13: 0.032229892 | BA13: 1.019671 | BB13: 456848.09 | BC13: 80985.942 | BD13: 0.96280476 | BE13: 421745.1 | BF13: 78162.891 | BG13: 5.2374302 | BH13: 4.101913 | BI13: 7.0175439 | BJ13: 0.04043428 | BK13: -0.00029538462 | BL13: 0.12600045 | BM13: 0.2483233 | BN13: 0.11655501 | BO13: 0.14386605 | BP13: 0.432 | BQ13: 0.13035937 | BR13: 2.4590448 | BS13: 29 | BT13: 13.550561 | BU13: 0.56 | BV13: 0.152 | BW13: 2.1373742 | BX13: 27 | BY13: 20.214276
A14: COBEN_CZCOBEN015 | B14: 17.040141 | C14: 0.60857143 | D14: 15.485062 | E14: 21.378592 | F14: 27.443105 | G14: 10.264835 | H14: 20.193797 | I14: 0.052592985 | J14: 0.0036580094 | K14: 0.0028674543 | L14: 0.062962708 | M14: 0.43765694 | N14: 0.36572663 | O14: 2.4553444 | P14: 0.74046316 | Q14: 3.3100304 | R14: 1.8991298 | S14: 8.948052 | T14: 1.82843 | U14: 0.0023287139 | V14: 0.0026485072 | W14: 0.0071098465 | X14: 0.0038614568 | Y14: 0.033892704 | Z14: 0.014086587 | AA14: 0.28277202 | AB14: 0.033792529 | AC14: 0.30938721 | AD14: -0.1635437 | AE14: 0.8041687 | AF14: -0.4394989 | AG14: 1.048233 | AH14: -1.1477356 | AI14: 1.916748 | AJ14: -1.4933472 | AK14: 0 | AL14: 0 | AM14: 0 | AN14: 0.065 | AO14: 0.6599801 | AP14: 0.62863884 | AQ14: 0.13662759 | AR14: 0.030123235 | AS14: 0.16747714 | AT14: 0.39555827 | AU14: 0.29012592 | AV14: 0.31531767 | AW14: 0.047383419 | AX14: 0.011423816 | AY14: 0.44553785 | AZ14: 0.17596068 | BA14: 0.97661929 | BB14: 217387.75 | BC14: 36613.952 | BD14: 1.0275608 | BE14: 253674.23 | BF14: 48305.177 | BG14: 6.270903 | BH14: 44.176973 | BI14: 42.222222 | BJ14: 0.1059905 | BK14: 0.00045454545 | BL14: 0.1511839 | BM14: 0.27500637 | BN14: 0.072023958 | BO14: 0.15453692 | BP14: 0.564 | BQ14: 0.2 | BR14: 3.3924881 | BS14: 16 | BT14: 10.454958 | BU14: 0.672 | BV14: 0.092 | BW14: 1.9918574 | BX14: 16 | BY14: 16.134883
A15: COBEN_CZCOBEN016 | B15: 15.270196 | C15: 0.53615385 | D15: 7.9700625 | E15: 19.261882 | F15: 20.205019 | G15: 18.87354 | H15: 18.001945 | I15: 0.058710206 | J15: 0.0065248763 | K15: 0.0091372203 | L15: 0.077633545 | M15: 1.1448538 | N15: 1.4393731 | O15: 1.1714735 | P15: 1.0722337 | Q15: 3.2782419 | R15: 2.8705806 | S15: 5.0909904 | T15: 2.325066 | U15: 0.0042834796 | V15: 0.0081810492 | W15: 0.0033772076 | X15: 0.0048628818 | Y15: 0.041826014 | Z15: 0.051543417 | AA15: 0.13095323 | AB15: 0.04097376 | AC15: 4.8983078 | AD15: 2.2577438 | AE15: 3.0723953 | AF15: -0.65106964 | AG15: 11.104652 | AH15: 6.7427139 | AI15: 0.99449921 | AJ15: -1.6259384 | AK15: 0 | AL15: 0 | AM15: 0 | AN15: 0.252 | AO15: 0.68886051 | AP15: 0.68628167 | AQ15: 0.44752276 | AR15: 0.046152609 | AS15: 0.10818069 | AT15: 0.37584405 | AU15: 0.28365121 | AV15: 0.29634004 | AW15: 0.35463936 | AX15: 0.012361581 | AY15: 0.042203833 | AZ15: 0.33020472 | BA15: 0.98858483 | BB15: 175602.83 | BC15: 34175.706 | BD15: 1.078321 | BE15: 195657.13 | BF15: 41342.937 | BG15: 5.5637982 | BH15: 4.101913 | BI15: 5.2631579 | BJ15: 0.058363531 | BK15: -0.0033234811 | BL15: 0.15749043 | BM15: 0.18712555 | BN15: 0.10833379 | BO15: 0.12455093 | BP15: 0.672 | BQ15: 0.224 | BR15: 2.3891252 | BS15: 24 | BT15: 15.257875 | BU15: 0.688 | BV15: 0.12 | BW15: 2.1972653 | BX15: 16 | BY15: 12.454754
A16: COBEN_CZCOBEN017 | B16: 8.4055595 | C16: 0.48857143 | D16: 12.567562 | E16: 21.451978 | F16: 23.965603 | G16: 21.689243 | H16: 20.655767 | I16: 0.031439702 | J16: 0.0017993159 | K16: 0.0097491048 | L16: 0.084810276 | M16: 0.76011869 | N16: 0.41022992 | O16: 0.4719434 | P16: 0.98040933 | Q16: 4.0760063 | R16: 3.272656 | S16: 5.5650856 | T16: 1.7240259 | U16: 0.0041647785 | V16: 0.0038893432 | W16: 0.0017867743 | X16: 0.0036242698 | Y16: 0.048936732 | Z16: 0.057481659 | AA16: 0.10258158 | AB16: 0.043167588 | AC16: -3.4848175 | AD16: 0.55058289 | AE16: 1.6186523 | AF16: 3.3563538 | AG16: -3.0443115 | AH16: 0.20436096 | AI16: 1.5665588 | AJ16: 0.086212158 | AK16: 0 | AL16: 0 | AM16: 0 | AN16: 0.239 | AO16: 0.58222911 | AP16: 0.64362596 | AQ16: 0.44811697 | AR16: 0.077538825 | AS16: 0.060157498 | AT16: 0.63730964 | AU16: 0.25542594 | AV16: 0.2882338 | AW16: 0.36947033 | AX16: 0.032085107 | AY16: 0.74006323 | AZ16: 0.38300637 | BA16: 1.1315317 | BB16: 731998.09 | BC16: 103705.26 | BD16: 1.1225146 | BE16: 356626.24 | BF16: 63288.92 | BG16: 4.7468354 | BH16: 5.99751 | BI16: 4.9382716 | BJ16: 0.06153122 | BK16: -0.019586813 | BL16: 0.16740087 | BM16: 0.19495204 | BN16: 0.079165584 | BO16: 0.12522467 | BP16: 0.528 | BQ16: 0.152 | BR16: 2.1772235 | BS16: 16 | BT16: 7.3480775 | BU16: 0.58 | BV16: 0.12 | BW16: 2.4654677 | BX16: 8 | BY16: 6.4442623
A17: COBEN_CZCOBEN018 | B17: 10.281785 | C17: 0.46 | D17: 16.725062 | E17: 16.696355 | F17: 28.70305 | G17: 28.151348 | H17: 13.467405 | I17: 0.52277603 | J17: 0.005978235 | K17: 0.038480829 | L17: 0.5405325 | M17: 2.0215604 | N17: 0.46246618 | O17: 0.59043585 | P17: 1.1610267 | Q17: 3.0992586 | R17: 2.4593882 | S17: 2.6052752 | T17: 2.9586766 | U17: 0.0039023205 | V17: 0.001946751 | W17: 0.0019440487 | X17: 0.0068537263 | Y17: 0.040297362 | Z17: 0.020554542 | AA17: 0.021516941 | AB17: 0.065673273 | AC17: 0.75418091 | AD17: 0.55738831 | AE17: -1.155304 | AF17: 4.359024 | AG17: 1.6819916 | AH17: 1.5615845 | AI17: 0.13807678 | AJ17: 2.279953 | AK17: 0.508 | AL17: 0 | AM17: 0 | AN17: 0.719 | AO17: 0.55422095 | AP17: 0.5982412 | AQ17: 0.16062131 | AR17: 0.049084885 | AS17: 0.048519048 | AT17: 0.22016707 | AU17: 0.26906103 | AV17: 0.28024834 | AW17: 0.042156011 | AX17: 0.22815108 | AY17: 0.058556511 | AZ17: 0.12868519 | BA17: 1.0370568 | BB17: 395576.6 | BC17: 63199.273 | BD17: 1.0054445 | BE17: 319679.86 | BF17: 53546.143 | BG17: 1.1234272 | BH17: 38.596159 | BI17: -4.2553191 | BJ17: 0.028525833 | BK17: 0.012 | BL17: 0.14804212 | BM17: 0.15805142 | BN17: 0.11803698 | BO17: 0.1837334 | BP17: 0.5 | BQ17: 0.156 | BR17: 2.7943238 | BS17: 13 | BT17: 6.096139 | BU17: 0.456 | BV17: 0.064 | BW17: 2.234356 | BX17: 9 | BY17: 7.21629
A18: COBEN_CZCOBEN019 | B18: 14.513878 | C18: 0.53533333 | D18: 15.172562 | E18: 21.699341 | F18: 26.775655 | G18: 28.914425 | H18: 19.38152 | I18: 1.4951725 | J18: 0.026043182 | K18: 0.044632965 | L18: 1.5262078 | M18: 0.45234495 | N18: 0.37694092 | O18: 0.24619893 | P18: 1.1363227 | Q18: 2.7066844 | R18: 2.8579523 | S18: 2.2015918 | T18: 1.1126572 | U18: 0.0026195461 | V18: 0.0016727307 | W18: 0.0014393677 | X18: 0.0029477568 | Y18: 0.027095758 | Z18: 0.029240617 | AA18: 0.0248116 | AB18: 0.033175897 | AC18: -1.3897247 | AD18: -0.45050049 | AE18: 0.21862793 | AF18: -1.4443359 | AG18: -1.1328278 | AH18: -0.70826721 | AI18: 0.68661499 | AJ18: -0.19845581 | AK18: 0 | AL18: 0 | AM18: 0 | AN18: 0.528 | AO18: 0.55333612 | AP18: 0.61244859 | AQ18: 0.027876319 | AR18: 0.017550198 | AS18: 0.026009616 | AT18: 0.10180595 | AU18: 0.245647 | AV18: 0.27203881 | AW18: 0.0086171705 | AX18: 0.011479367 | AY18: 0.02529277 | AZ18: 0.032494424 | BA18: 0.81050144 | BB18: 150545.81 | BC18: 25948.314 | BD18: 0.99928533 | BE18: 261254.63 | BF18: 47479.276 | BG18: =MEDIAN!BG3 -> 5.2301357 | BH18: =MEDIAN!BH3 -> 6.1937647 | BI18: =MEDIAN!BI3 -> 3.6700337 | BJ18: =MEDIAN!BJ3 -> 0.038052591 | BK18: =MEDIAN!BK3 -> -0.0048842105 | BL18: 0.23596343 | BM18: 0.22156043 | BN18: 0.056718893 | BO18: 0.18342746 | BP18: 1.048 | BQ18: 0.504 | BR18: 2.9783087 | BS18: 29 | BT18: 17.324814 | BU18: 0.596 | BV18: 0.14 | BW18: 2.3371463 | BX18: 17 | BY18: 12.237192
A19: COBEN_CZCOBEN021 | B19: 18.202121 | C19: 0.54357143 | D19: 36.410063 | E19: 24.176423 | F19: 23.646893 | G19: 27.841578 | H19: 21.009931 | I19: 0.78698939 | J19: 0.011928179 | K19: 0.030477869 | L19: 0.5693539 | M19: 0.64799534 | N19: 0.41540965 | O19: 0.55036144 | P19: 0.54276713 | Q19: 2.2177992 | R19: 1.8577875 | S19: 1.7330929 | T19: 2.0737291 | U19: 0.0019262121 | V19: 0.0013849701 | W19: 0.0018305752 | X19: 0.0027098058 | Y19: 0.019687187 | Z19: 0.016487405 | AA19: 0.022024618 | AB19: 0.035220523 | AC19: -0.16114807 | AD19: 0.54175568 | AE19: 0.55002594 | AF19: -1.7041626 | AG19: -0.038017273 | AH19: 0.64666748 | AI19: 0.61024475 | AJ19: -0.83447266 | AK19: 0 | AL19: 0 | AM19: 0 | AN19: 0.192 | AO19: 0.7173911 | AP19: 0.69523158 | AQ19: 0.059528076 | AR19: 0.016814069 | AS19: 0.040988564 | AT19: 0.18876273 | AU19: 0.30267766 | AV19: 0.32596894 | AW19: 0.48300036 | AX19: 0.018862183 | AY19: 0.080082548 | AZ19: 0.55747007 | BA19: 1.1697201 | BB19: 153988.43 | BC19: 30644.838 | BD19: 1.120868 | BE19: 227729.64 | BF19: 39124.407 | BG19: 3.9556962 | BH19: 46.444796 | BI19: -11.764706 | BJ19: 0.14619291 | BK19: -0.0010734945 | BL19: 0.15581927 | BM19: 0.14429109 | BN19: 0.069181006 | BO19: 0.087672509 | BP19: 0.512 | BQ19: 0.16 | BR19: 2.1572802 | BS19: 24 | BT19: 12.089024 | BU19: 0.52 | BV19: 0.152 | BW19: 2.0358458 | BX19: 19 | BY19: 14.338162
A20: COBEN_CZCOBEN022 | B20: 20.179924 | C20: 0.68666667 | D20: 16.575063 | E20: 3.2176326 | F20: 28.587659 | G20: 28.909432 | H20: 10.164731 | I20: 2.601548 | J20: 0.0026649936 | K20: 0.13670119 | L20: 4.4446506 | M20: 1.490031 | N20: 0.51404255 | O20: 0.66903895 | P20: 1.8989982 | Q20: 3.4675904 | R20: 1.6653454 | S20: 2.6291426 | T20: 2.1037731 | U20: 0.013055896 | V20: 0.0019086974 | W20: 0.0026504506 | X20: 0.013185099 | Y20: 0.25443737 | Z20: 0.018446865 | AA20: 0.028625124 | AB20: 0.065434908 | AC20: -0.49371338 | AD20: 1.4733276 | AE20: -0.5607605 | AF20: 0.93008423 | AG20: 4.8526917 | AH20: 3.5299377 | AI20: 0.49176025 | AJ20: 2.2375717 | AK20: 6.091 | AL20: 0 | AM20: 0 | AN20: 6.771 | AO20: 0.55757394 | AP20: 0.57739479 | AQ20: 0.030959631 | AR20: 0.069719714 | AS20: 0.03291528 | AT20: 0.091675886 | AU20: 0.26302042 | AV20: 0.27854638 | AW20: 0.025258937 | AX20: 0.084978442 | AY20: 0.026475745 | AZ20: 0.087648025 | BA20: 1.1354517 | BB20: 488034.27 | BC20: 75985.816 | BD20: 1.1353851 | BE20: 487270.39 | BF20: 72252.417 | BG20: 5.0813008 | BH20: 5.7413381 | BI20: -8.3333333 | BJ20: 0.053967548 | BK20: -0.0057212121 | BL20: 0.22586083 | BM20: 0.27013644 | BN20: 0.21035736 | BO20: 0.2021783 | BP20: 0.736 | BQ20: 0.224 | BR20: 2.616477 | BS20: 31 | BT20: 26.544439 | BU20: 0.704 | BV20: 0.24 | BW20: 2.3063728 | BX20: 30 | BY20: 23.094801
A21: COBEN_CZCOBEN023 | B21: 18.771371 | C21: 0.82045455 | D21: 19.012563 | E21: 19.51361 | F21: 25.474835 | G21: 13.899247 | H21: 17.045948 | I21: 0.92425926 | J21: 0.01138944 | K21: 0.086116008 | L21: 0.98402729 | M21: 0.95556719 | N21: 1.0997235 | O21: 0.82318247 | P21: 1.0531274 | Q21: 2.0407134 | R21: 1.7445087 | S21: 5.0241077 | T21: 1.5299775 | U21: 0.0039542057 | V21: 0.003065017 | W21: 0.004202164 | X21: 0.0052126538 | Y21: 0.0277631 | Z21: 0.016088185 | AA21: 0.12456092 | AB21: 0.037875888 | AC21: -1.3581314 | AD21: -2.1532288 | AE21: 0.34158325 | AF21: -0.75576019 | AG21: -0.25881195 | AH21: -1.2553711 | AI21: 0.65713501 | AJ21: -1.8553467 | AK21: 0 | AL21: 0 | AM21: 0 | AN21: 0.474 | AO21: 0.60947212 | AP21: 0.62541106 | AQ21: 0.012503438 | AR21: 0.017137936 | AS21: 0.036634172 | AT21: 0.048667409 | AU21: 0.26814355 | AV21: 0.27407834 | AW21: 0.010065654 | AX21: 0.0077727599 | AY21: 0.045729697 | AZ21: 0.039722122 | BA21: 0.95315807 | BB21: 270599.37 | BC21: 43733.755 | BD21: 0.97547347 | BE21: 252614.06 | BF21: 43937.595 | BG21: 6.2292359 | BH21: 8.7223513 | BI21: 12.244898 | BJ21: 0.082545369 | BK21: 0.001029601 | BL21: 0.24187762 | BM21: 0.20272265 | BN21: 0.10207795 | BO21: 0.12651056 | BP21: 1.008 | BQ21: 0.472 | BR21: 2.0106806 | BS21: 25 | BT21: 24.532452 | BU21: 0.956 | BV21: 0.312 | BW21: 2.3377988 | BX21: 24 | BY21: 24.207248
A22: COBEN_CZCOBEN024 | B22: 17.40037 | C22: 0.56952381 | D22: 29.405062 | E22: 20.362266 | F22: 18.333508 | G22: 23.432214 | H22: 21.599725 | I22: 3.6088233 | J22: 0.021706891 | K22: 0.026782043 | L22: 2.7858884 | M22: 0.62960821 | N22: 0.59463432 | O22: 0.52245321 | P22: 0.49214699 | Q22: 3.5043712 | R22: 4.0666124 | S22: 3.4608793 | T22: 2.6820225 | U22: 0.0025561759 | V22: 0.0015983336 | W22: 0.00086251164 | X22: 0.0018206388 | Y22: 0.041467135 | Z22: 0.072842709 | AA22: 0.1031056 | AB22: 0.033412648 | AC22: -1.4680939 | AD22: 1.6581726 | AE22: 0.82293701 | AF22: -1.4095306 | AG22: -0.52204895 | AH22: -0.18505859 | AI22: 0.040222168 | AJ22: -1.4307098 | AK22: 0 | AL22: 0 | AM22: 0 | AN22: 0.102 | AO22: 0.60888563 | AP22: 0.62652574 | AQ22: 0.024836144 | AR22: 0.025641441 | AS22: 0.013757702 | AT22: 0.082989124 | AU22: 0.28426751 | AV22: 0.30735885 | AW22: 0.01244303 | AX22: 0.060280858 | AY22: 0.037016447 | AZ22: 0.053663936 | BA22: 1.0014212 | BB22: 347494.36 | BC22: 46002.185 | BD22: 1.087586 | BE22: 373580.39 | BF22: 54624.867 | BG22: 2.2007042 | BH22: 32.774482 | BI22: 35 | BJ22: 0.041627603 | BK22: 0.0056701754 | BL22: 0.2352872 | BM22: 0.19880105 | BN22: 0.0692586 | BO22: 0.14310447 | BP22: 0.624 | BQ22: 0.28 | BR22: 3.0857352 | BS22: 23 | BT22: 15.962589 | BU22: 0.46 | BV22: 0.144 | BW22: 2.7265345 | BX22: 25 | BY22: 15.115122
A23: COBEN_CZCOBEN025 | B23: 15.487743 | C23: 0.59647059 | D23: 12.472563 | E23: 25.692009 | F23: 31.952162 | G23: 16.620459 | H23: 22.716467 | I23: 1.441092 | J23: 0.0095522492 | K23: 0.06789189 | L23: 1.3347597 | M23: 0.55966133 | N23: 0.49319729 | O23: 0.45047181 | P23: 1.1764476 | Q23: 2.5144874 | R23: 1.9648259 | S23: 4.9410547 | T23: 3.0352074 | U23: 0.0011960913 | V23: 0.00099300444 | W23: 0.0015548869 | X23: 0.0023012483 | Y23: 0.017123752 | Z23: 0.0089380026 | AA23: 0.13546084 | AB23: 0.033981363 | AC23: 0.26393127 | AD23: 0.37722778 | AE23: 0.51025391 | AF23: 1.2995911 | AG23: 2.0644684 | AH23: 3.4053955 | AI23: 0.87623596 | AJ23: 4.0817413 | AK23: 0 | AL23: 0 | AM23: 0 | AN23: 1.206 | AO23: 0.67968147 | AP23: 0.63917278 | AQ23: 0.054108366 | AR23: 0.030885102 | AS23: 0.026611579 | AT23: 0.078546614 | AU23: 0.28301106 | AV23: 0.27997787 | AW23: 0.01599521 | AX23: 0.0084372795 | AY23: 0.024418491 | AZ23: 0.030162246 | BA23: 1.1355809 | BB23: 602011.47 | BC23: 108161.78 | BD23: 1.0426354 | BE23: 550714.41 | BF23: 93667.87 | BG23: =MEDIAN!BG$3 -> 5.2301357 | BH23: =MEDIAN!BH$3 -> 6.1937647 | BI23: =MEDIAN!BI$3 -> 3.6700337 | BJ23: 0.027586207 | BK23: -0.024 | BL23: 0.27493075 | BM23: 0.27179382 | BN23: 0.083910173 | BO23: 0.097876388 | BP23: 0.616 | BQ23: 0.12 | BR23: 2.2142614 | BS23: 18 | BT23: 10.754161 | BU23: 0.66 | BV23: 0.128 | BW23: 2.6089708 | BX23: 18 | BY23: 14.899782
A24: COBEN_CZCOBEN026 | B24: 26.336902 | C24: 0.64487179 | D24: 29.677563 | E24: 20.77785 | F24: 26.696559 | G24: 25.017053 | H24: 21.517044 | I24: 0.86095944 | J24: 0.0090251924 | K24: 0.018764753 | L24: 1.6946939 | M24: 0.62451885 | N24: 0.29312264 | O24: 0.34049267 | P24: 0.43091347 | Q24: 3.0890599 | R24: 3.0417353 | S24: 3.8480362 | T24: 3.4341808 | U24: 0.0018766861 | V24: 0.0011676731 | W24: 0.00081573904 | X24: 0.0017611836 | Y24: 0.027183321 | Z24: 0.020710296 | AA24: 0.055602472 | AB24: 0.048782584 | AC24: -1.7674713 | AD24: 0.46607971 | AE24: -0.60510254 | AF24: 0.4750061 | AG24: -1.8400116 | AH24: 0.24368286 | AI24: -0.27409363 | AJ24: 0.35464478 | AK24: 0 | AL24: 0 | AM24: 0 | AN24: 0.135 | AO24: 0.577246 | AP24: 0.60750064 | AQ24: 0.041624517 | AR24: 0.012847409 | AS24: 0.09801788 | AT24: 0.27925892 | AU24: 0.26713801 | AV24: 0.264327 | AW24: 0.20790411 | AX24: 0.020339845 | AY24: 0.32177236 | AZ24: 0.32258248 | BA24: 0.9666809 | BB24: 238017.68 | BC24: 39553.134 | BD24: 0.97805602 | BE24: 226398.21 | BF24: 37094.274 | BG24: 4.350348 | BH24: 2.795085 | BI24: 4.3368087e-14 | BJ24: 0.028133981 | BK24: -0.00090767519 | BL24: 0.13273524 | BM24: 0.1832299 | BN24: 0.18723762 | BO24: 0.19384905 | BP24: 0.88 | BQ24: 0.456 | BR24: 2.2825678 | BS24: 32 | BT24: 29.617573 | BU24: 0.696 | BV24: 0.312 | BW24: 2.3686316 | BX24: 41 | BY24: 27.514569
A25: COBEN_CZCOBEN027 | B25: 26.420788 | C25: 0.46096774 | D25: 6.6275625 | E25: 17.135765 | F25: 13.688287 | G25: 13.977522 | H25: 17.836439 | I25: 17.945124 | J25: 0.017675014 | K25: 0.055249339 | L25: 6.9189148 | M25: 0.41551573 | N25: 0.52218581 | O25: 1.0608451 | P25: 0.45047952 | Q25: 4.9652518 | R25: 2.9824657 | S25: 3.606857 | T25: 2.8200165 | U25: 0.0015210634 | V25: 0.0037871779 | W25: 0.0081658017 | X25: 0.0029094591 | Y25: 0.079206706 | Z25: 0.12190456 | AA25: 0.1228381 | AB25: 0.11590501 | AC25: 0.47039795 | AD25: -0.1268158 | AE25: 2.7413025 | AF25: 0.19134521 | AG25: -0.11982727 | AH25: -1.7485657 | AI25: 4.4750977 | AJ25: -0.14816284 | AK25: 0 | AL25: 0 | AM25: 0 | AN25: 0.152 | AO25: 0.52900879 | AP25: 0.51638082 | AQ25: 0.10034593 | AR25: 0.052683087 | AS25: 0.35897938 | AT25: 0.10513442 | AU25: 0.25972258 | AV25: 0.26388868 | AW25: 0.15686351 | AX25: 0.085049607 | AY25: 0.19709968 | AZ25: 0.14606558 | BA25: 0.95672539 | BB25: 271992.78 | BC25: 39864.307 | BD25: 1.0718746 | BE25: 249853.06 | BF25: 44714.35 | BG25: =MEDIAN!BG$3 -> 5.2301357 | BH25: =MEDIAN!BH$3 -> 6.1937647 | BI25: =MEDIAN!BI$3 -> 3.6700337 | BJ25: 0.018032787 | BK25: -0.0816 | BL25: 0.082493813 | BM25: 0.11424007 | BN25: 0.097792331 | BO25: 0.11871909 | BP25: 0.732 | BQ25: 0.24 | BR25: 2.6226152 | BS25: 34 | BT25: 14.819267 | BU25: 0.792 | BV25: 0.184 | BW25: 2.125104 | BX25: 40 | BY25: 18.406482
A26: COBEN_CZCOBEN029 | B26: 16.228384 | C26: 0.46266667 | D26: 15.417563 | E26: 24.275294 | F26: 27.404708 | G26: 31.108897 | H26: 23.591354 | I26: 0.74711382 | J26: 0.018921726 | K26: 0.0067653075 | L26: 0.54335042 | M26: 0.47885423 | N26: 0.3169165 | O26: 0.36118535 | P26: 0.55387564 | Q26: 1.8044911 | R26: 1.1102889 | S26: 1.2657199 | T26: 0.92458498 | U26: 0.0020475436 | V26: 0.0012106821 | W26: 0.0014273052 | X26: 0.0025209646 | Y26: 0.015149621 | Z26: 0.0074801727 | AA26: 0.016884334 | AB26: 0.015238601 | AC26: -0.21360779 | AD26: -2.092041 | AE26: -1.3699341 | AF26: -1.2038269 | AG26: 0.82801819 | AH26: -1.8840485 | AI26: -0.99745178 | AJ26: -0.98429871 | AK26: 0 | AL26: 0 | AM26: 0 | AN26: 0 | AO26: 0.67819188 | AP26: 0.71128653 | AQ26: 0.025567877 | AR26: 0.021962705 | AS26: 0.072188701 | AT26: 0.051552766 | AU26: 0.2783593 | AV26: 0.33075611 | AW26: 0.033450053 | AX26: 0.003643481 | AY26: 0.089520844 | AZ26: 0.035815234 | BA26: 1.2493555 | BB26: 579872.26 | BC26: 106046.28 | BD26: 1.2496789 | BE26: 599050.98 | BF26: 115129.76 | BG26: =MEDIAN!BG$3 -> 5.2301357 | BH26: =MEDIAN!BH$3 -> 6.1937647 | BI26: =MEDIAN!BI$3 -> 3.6700337 | BJ26: 0.1843772 | BK26: -0.08 | BL26: 0.16761042 | BM26: 0.20301606 | BN26: 0.16900256 | BO26: 0.15070317 | BP26: 0.608 | BQ26: 0.248 | BR26: 1.7996704 | BS26: 23 | BT26: 14.324791 | BU26: 0.46 | BV26: 0.088 | BW26: 2.1927125 | BX26: 18 | BY26: 11.570237
A27: COBEN_CZCOBEN030 | B27: 17.304413 | C27: 0.502 | D27: 23.942563 | E27: 30.474287 | F27: 29.514728 | G27: 19.938687 | H27: 26.088204 | I27: 3.271696 | J27: 0.0094651478 | K27: 0.012509835 | L27: 4.4996376 | M27: 0.21678067 | N27: 0.52649882 | O27: 0.67475034 | P27: 0.29605062 | Q27: 1.100442 | R27: 2.4461918 | S27: 3.6247743 | T27: 1.0674204 | U27: 0.00092694238 | V27: 0.0010259556 | W27: 0.0011542152 | X27: 0.0016115143 | Y27: 0.0094194267 | Z27: 0.022088627 | AA27: 0.07152461 | AB27: 0.01550156 | AC27: -0.17636108 | AD27: 1.6884766 | AE27: -2.8750305 | AF27: 0.42391968 | AG27: 0.8469696 | AH27: 0.98544312 | AI27: -0.84788513 | AJ27: -1.4720154 | AK27: 0 | AL27: 0 | AM27: 0 | AN27: 0.084 | AO27: 0.70342005 | AP27: 0.63052983 | AQ27: 0.0065104783 | AR27: 0.023668327 | AS27: 0.017325255 | AT27: 0.07250438 | AU27: 0.33198285 | AV27: 0.31796029 | AW27: 0.0036578115 | AX27: 0.097757537 | AY27: 0.088607784 | AZ27: 0.043175125 | BA27: 1.1222381 | BB27: 497779.47 | BC27: 102741.51 | BD27: 1.165964 | BE27: 471159.53 | BF27: 89201.944 | BG27: 3.7650602 | BH27: 16.576071 | BI27: 1.9047944e-13 | BJ27: 0.037791995 | BK27: -0.012643357 | BL27: 0.12997003 | BM27: 0.18790368 | BN27: 0.13796575 | BO27: 0.13382452 | BP27: 0.42 | BQ27: 0.056 | BR27: 2.152664 | BS27: 17 | BT27: 7.5645455 | BU27: 0.544 | BV27: 0.112 | BW27: 2.8091284 | BX27: 28 | BY27: 13.750828
A28: COBEN_CZCOBEN032 | B28: 18.074748 | C28: 0.6075 | D28: 15.662562 | E28: 19.604423 | F28: 18.900499 | G28: 23.504014 | H28: 19.538577 | I28: 2.1841224 | J28: 0.024989613 | K28: 0.036741274 | L28: 4.2579116 | M28: 0.65701431 | N28: 0.84502415 | O28: 0.81329619 | P28: 2.0694039 | Q28: 3.5577603 | R28: 4.3660285 | S28: 3.333859 | T28: 2.6841153 | U28: 0.0038314697 | V28: 0.0039483154 | W28: 0.0070659872 | X28: 0.0026748043 | Y28: 0.03700778 | Z28: 0.035090136 | AA28: 0.027718468 | AB28: 0.040476403 | AC28: 0.28501892 | AD28: -2.9708862 | AE28: 1.3472137 | AF28: 0.47148132 | AG28: -1.9419403 | AH28: -4.4983521 | AI28: 1.7281342 | AJ28: -5.6385193 | AK28: 0 | AL28: 0 | AM28: 0 | AN28: 0 | AO28: 0.53765076 | AP28: 0.53212399 | AQ28: 0.041473779 | AR28: 0.051640439 | AS28: 0.0065888019 | AT28: 0.033907477 | AU28: 0.26017905 | AV28: 0.26809317 | AW28: 0.065411241 | AX28: 0.14386528 | AY28: 0.036130926 | AZ28: 0.043798483 | BA28: 0.95904413 | BB28: 238934.67 | BC28: 44553.659 | BD28: 0.90549337 | BE28: 252564.37 | BF28: 44969.869 | BG28: 5.3267045 | BH28: 6.1514337 | BI28: 7.1428571 | BJ28: 0.034117901 | BK28: -0.0039272727 | BL28: 0.12414996 | BM28: 0.17963335 | BN28: 0.091182406 | BO28: 0.15017175 | BP28: 0.496 | BQ28: 0.2 | BR28: 3.7947341 | BS28: 25 | BT28: 11.722041 | BU28: 0.748 | BV28: 0.248 | BW28: 2.4290721 | BX28: 22 | BY28: 17.431178
A29: COBEN_CZCOBEN033 | B29: 38.400329 | C29: 0.47538462 | D29: 5.112125 | E29: 17.527399 | F29: 20.250046 | G29: 9.6717676 | H29: 15.348008 | I29: 0.37117066 | J29: 0.01255323 | K29: 0.0080311691 | L29: 0.29730083 | M29: 0.51487295 | N29: 0.51350006 | O29: 1.0215047 | P29: 0.70233609 | Q29: 2.5285805 | R29: 2.1556371 | S29: 7.8680819 | T29: 2.7032294 | U29: 0.0028907504 | V29: 0.0034543525 | W29: 0.0044445932 | X29: 0.0043194223 | Y29: 0.033307248 | Z29: 0.015571279 | AA29: 0.12528709 | AB29: 0.05057219 | AC29: -1.427002 | AD29: -0.68469238 | AE29: 0.61428833 | AF29: -2.3569336 | AG29: -2.1086578 | AH29: -0.69328308 | AI29: -0.90663147 | AJ29: -2.2879639 | AK29: 0 | AL29: 0 | AM29: 0 | AN29: 0.984 | AO29: 0.49475258 | AP29: 0.46731738 | AQ29: 0.40435137 | AR29: 0.036026682 | AS29: 0.35492478 | AT29: 0.45066183 | AU29: 0.27093287 | AV29: 0.27357018 | AW29: 0.46263516 | AX29: 0.014029377 | AY29: 0.42865236 | AZ29: 0.4229883 | BA29: 1.1215225 | BB29: 468045.25 | BC29: 81607.934 | BD29: 1.0403069 | BE29: 457445.29 | BF29: 78312.726 | BG29: =MEDIAN!BG$3 -> 5.2301357 | BH29: =MEDIAN!BH$3 -> 6.1937647 | BI29: =MEDIAN!BI$3 -> 3.6700337 | BJ29: 0.030111206 | BK29: -0.021028571 | BL29: 0.19044069 | BM29: 0.21321602 | BN29: 0.11328434 | BO29: 0.12525082 | BP29: 0.472 | BQ29: 0.128 | BR29: 1.9855058 | BS29: 42 | BT29: 23.112309 | BU29: 0.432 | BV29: 0.084 | BW29: 2.0373462 | BX29: 42 | BY29: 29.562158
A30: COBEN_CZCOBEN034 | B30: 21.558364 | C30: 0.48363636 | D30: 23.895688 | E30: 21.120486 | F30: 23.758995 | G30: 25.812872 | H30: 20.167319 | I30: 0.42339835 | J30: 0.01425921 | K30: 0.014257651 | L30: 0.37559693 | M30: 0.31555611 | N30: 0.39905661 | O30: 0.53211415 | P30: 0.37091503 | Q30: 3.4947758 | R30: 2.7748 | S30: 2.0838032 | T30: 2.2171562 | U30: 0.0013335286 | V30: 0.0018693413 | W30: 0.0020334667 | X30: 0.0016627262 | Y30: 0.040375323 | Z30: 0.038976487 | AA30: 0.030768849 | AB30: 0.05009954 | AC30: -0.34494019 | AD30: 0.130867 | AE30: 0.52751923 | AF30: 1.9297791 | AG30: -0.53038788 | AH30: 0.090400696 | AI30: -0.81846619 | AJ30: 2.392952 | AK30: 0 | AL30: 0 | AM30: 0 | AN30: 0.21 | AO30: 0.57473148 | AP30: 0.62579059 | AQ30: 0.017755887 | AR30: 0.017733816 | AS30: 0.060487134 | AT30: 0.23501205 | AU30: 0.28747182 | AV30: 0.3124433 | AW30: 0.012019273 | AX30: 0.022544397 | AY30: 0.72672063 | AZ30: 0.29822229 | BA30: 0.97715479 | BB30: 132717.28 | BC30: 26058.486 | BD30: 0.99142442 | BE30: 164775.55 | BF30: 32404.672 | BG30: 5.2374302 | BH30: 5.5555556 | BI30: -6.9444444 | BJ30: 0.051394803 | BK30: -0.0090325123 | BL30: 0.091762624 | BM30: 0.13658452 | BN30: 0.11441541 | BO30: 0.18937562 | BP30: 0.904 | BQ30: 0.336 | BR30: 2.5165017 | BS30: 26 | BT30: 11.064135 | BU30: 0.628 | BV30: 0.164 | BW30: 2.6716474 | BX30: 25 | BY30: 16.413101
A31: COBEN_CZCOBEN035 | B31: 20.941525 | C31: 0.58602941 | D31: 12.360875 | E31: 27.073339 | F31: 31.405444 | G31: 28.693393 | H31: 27.991228 | I31: 1.721902 | J31: 0.010198726 | K31: 0.12140297 | L31: 2.7236552 | M31: 0.30392356 | N31: 0.23503907 | O31: 0.21770359 | P31: 0.30509357 | Q31: 1.7658307 | R31: 1.6287202 | S31: 2.846171 | T31: 0.88911104 | U31: 0.001466578 | V31: 0.0010479078 | W31: 0.00087749195 | X31: 0.0014890792 | Y31: 0.010364417 | Z31: 0.0063409886 | AA31: 0.042724412 | AB31: 0.011703452 | AC31: 0.22216797 | AD31: 0.76615906 | AE31: -0.0043640137 | AF31: -0.9655304 | AG31: 0.43505859 | AH31: 1.20047 | AI31: -0.073501587 | AJ31: 1.114624 | AK31: 0 | AL31: 0 | AM31: 0 | AN31: 0.324 | AO31: 0.63231099 | AP31: 0.49907781 | AQ31: 0.011277476 | AR31: 0.018064656 | AS31: 0.030587719 | AT31: 0.022738009 | AU31: 0.27542231 | AV31: 0.25495399 | AW31: 0.0089502881 | AX31: 0.0076116645 | AY31: 0.020179078 | AZ31: 0.017444821 | BA31: 0.98120363 | BB31: 460246.16 | BC31: 81144.358 | BD31: 1.0517242 | BE31: 406209.19 | BF31: 71822.372 | BG31: 4.222973 | BH31: 4.3758885 | BI31: 3.1746032 | BJ31: 0.02710695 | BK31: 0.0023026087 | BL31: 0.16739849 | BM31: 0.1368345 | BN31: 0.12686339 | BO31: 0.12611887 | BP31: 0.632 | BQ31: 0.256 | BR31: 1.9125909 | BS31: 29 | BT31: 22.56603 | BU31: 0.924 | BV31: 0.552 | BW31: 2.9568421 | BX31: 89 | BY31: 17.827748
A32: COBEN_CZCOBEN036 | B32: 20.110591 | C32: 0.52 | D32: 13.186312 | E32: 25.86571 | F32: 27.117665 | G32: 20.083503 | H32: 25.016169 | I32: 0.84668795 | J32: 0.0082965302 | K32: 0.014484932 | L32: 0.90945713 | M32: 0.77793756 | N32: 0.5022805 | O32: 0.44205064 | P32: 1.2693452 | Q32: 1.8093238 | R32: 2.9683898 | S32: 4.7093431 | T32: 1.6631391 | U32: 0.0018291589 | V32: 0.0022564655 | W32: 0.0028284748 | X32: 0.0023258737 | Y32: 0.012526255 | Z32: 0.03093242 | AA32: 0.081913961 | AB32: 0.016872643 | AC32: 0.91436768 | AD32: 2.2619324 | AE32: 0.4382019 | AF32: -2.3710022 | AG32: 2.0741119 | AH32: -2.238739 | AI32: 0.79702759 | AJ32: -1.1639709 | AK32: 0 | AL32: 0 | AM32: 0 | AN32: 0.76 | AO32: 0.62205769 | AP32: 0.60800715 | AQ32: 0.047602019 | AR32: 0.016831591 | AS32: 0.060120385 | AT32: 0.059348841 | AU32: 0.28037471 | AV32: 0.29386663 | AW32: 0.025475009 | AX32: 0.027754867 | AY32: 0.31167618 | AZ32: 0.049723989 | BA32: 1.0204216 | BB32: 349443.71 | BC32: 57867.382 | BD32: 1.102135 | BE32: 335940.13 | BF32: 61173.038 | BG32: =MEDIAN!BG$3 -> 5.2301357 | BH32: =MEDIAN!BH$3 -> 6.1937647 | BI32: =MEDIAN!BI$3 -> 3.6700337 | BJ32: 0.044591611 | BK32: 0.008 | BL32: 0.12111032 | BM32: 0.15701955 | BN32: 0.094671818 | BO32: 0.081646956 | BP32: 0.72 | BQ32: 0.264 | BR32: 2.2215798 | BS32: 18 | BT32: 19.504854 | BU32: 0.536 | BV32: 0.144 | BW32: 2.3531358 | BX32: 24 | BY32: 17.107968
A33: COBEN_CZCOBEN038 | B33: 19.690632 | C33: 0.65791667 | D33: 7.6381875 | E33: 17.408947 | F33: 21.196973 | G33: 25.701607 | H33: 15.149355 | I33: 4.1544619 | J33: 0.024057344 | K33: 0.046787793 | L33: 3.9536925 | M33: 0.55701977 | N33: 0.45352369 | O33: 0.35755481 | P33: 1.4623175 | Q33: 2.739994 | R33: 2.5836249 | S33: 3.2608764 | T33: 1.7319353 | U33: 0.0039372237 | V33: 0.004465992 | W33: 0.0023385125 | X33: 0.0043372463 | Y33: 0.03416737 | Z33: 0.023174777 | AA33: 0.032740439 | AB33: 0.034220539 | AC33: -0.68196106 | AD33: 0.43121338 | AE33: 0.53025818 | AF33: -2.393219 | AG33: -1.7911987 | AH33: -0.39215088 | AI33: 0.58621216 | AJ33: -2.8510284 | AK33: 0 | AL33: 0 | AM33: 0 | AN33: 2.5 | AO33: 0.4844602 | AP33: 0.60579785 | AQ33: 0.023561564 | AR33: 0.026515344 | AS33: 0.0082883506 | AT33: 0.040923058 | AU33: 0.22043369 | AV33: 0.26665521 | AW33: 0.013916563 | AX33: 0.0078246849 | AY33: 0.015401631 | AZ33: 0.019092175 | BA33: 0.95574541 | BB33: 445597.41 | BC33: 70646.298 | BD33: 0.99710327 | BE33: 410356.13 | BF33: 67665.421 | BG33: =MEDIAN!BG$3 -> 5.2301357 | BH33: =MEDIAN!BH$3 -> 6.1937647 | BI33: =MEDIAN!BI$3 -> 3.6700337 | BJ33: 0.081855501 | BK33: -0.04152381 | BL33: 0.23224163 | BM33: 0.22836119 | BN33: 0.079765955 | BO33: 0.18347704 | BP33: 1.024 | BQ33: 0.64 | BR33: 2.8659449 | BS33: 41 | BT33: 21.860252 | BU33: 0.6 | BV33: 0.128 | BW33: 2.0336993 | BX33: 27 | BY33: 20.188975
A34: COBEN_CZCOBEN039 | B34: 16.061766 | C34: 0.80913043 | D34: 9.9050625 | E34: 26.904212 | F34: 29.719697 | G34: 9.7875078 | H34: 25.157001 | I34: 0.24519237 | J34: 0.0031415336 | K34: 0.023055275 | L34: 0.26835552 | M34: 0.53443679 | N34: 0.70353496 | O34: 0.92157122 | P34: 0.64473116 | Q34: 1.5828304 | R34: 1.2684027 | S34: 7.115603 | T34: 1.4748426 | U34: 0.0020497555 | V34: 0.0013147049 | W34: 0.0048128149 | X34: 0.0022761514 | Y34: 0.01831015 | Z34: 0.013323918 | AA34: 0.2019291 | AB34: 0.01855687 | AC34: -0.12149811 | AD34: -0.29325867 | AE34: 1.5890198 | AF34: 1.7919159 | AG34: 0.64295959 | AH34: 1.2961807 | AI34: 2.0618896 | AJ34: 0.62697601 | AK34: 0 | AL34: 0 | AM34: 0 | AN34: 0.101 | AO34: 0.51040272 | AP34: 0.64988221 | AQ34: 0.1618829 | AR34: 0.010368619 | AS34: 0.057885973 | AT34: 0.21785867 | AU34: 0.25213585 | AV34: 0.27970125 | AW34: 0.48455293 | AX34: 0.014250982 | AY34: 0.095780116 | AZ34: 0.4941052 | BA34: 1.0419673 | BB34: 134332.17 | BC34: 28485.413 | BD34: 0.7705614 | BE34: 338638.09 | BF34: 51530.834 | BG34: =MEDIAN!BG$3 -> 5.2301357 | BH34: =MEDIAN!BH$3 -> 6.1937647 | BI34: =MEDIAN!BI$3 -> 3.6700337 | BJ34: 0.045180723 | BK34: -0.0272 | BL34: 0.10996564 | BM34: 0.14099709 | BN34: 0.12036629 | BO34: 0.1064529 | BP34: 0.904 | BQ34: 0.488 | BR34: 2.4274287 | BS34: 33 | BT34: 23.380813 | BU34: 0.784 | BV34: 0.296 | BW34: 2.0973653 | BX34: 26 | BY34: 19.963951
A35: COBEN_CZCOBEN040 | B35: 23.41996 | C35: 0.83962963 | D35: 12.774563 | E35: 24.191768 | F35: 23.92133 | G35: 26.49717 | H35: 23.326384 | I35: 0.91286115 | J35: 0.010697398 | K35: 0.011372493 | L35: 1.0501066 | M35: 0.37947957 | N35: 1.7702145 | O35: 0.48436096 | P35: 0.48671981 | Q35: 2.2118397 | R35: 2.2325004 | S35: 2.3971388 | T35: 1.1282861 | U35: 0.0011538615 | V35: 0.002166628 | W35: 0.0010499631 | X35: 0.001779408 | Y35: 0.0190665 | Z35: 0.032539884 | AA35: 0.024578906 | AB35: 0.022095428 | AC35: 0.3366394 | AD35: -1.033844 | AE35: 0.19897461 | AF35: -0.22234344 | AG35: 0.81594086 | AH35: -0.31245422 | AI35: 0.15979767 | AJ35: 0.29319763 | AK35: 0 | AL35: 0 | AM35: 0 | AN35: 0 | AO35: =MEDIAN!AO3 -> 0.62038545 | AP35: 0.60324715 | AQ35: 0.02576024 | AR35: 0.035850196 | AS35: 0.022778806 | AT35: 0.053131792 | AU35: =MEDIAN!AU3 -> 0.27781266 | AV35: 0.26849165 | AW35: 0.0072839495 | AX35: 0.0097957718 | AY35: 0.028923224 | AZ35: 0.015609635 | BA35: =MEDIAN!BA3 -> 1.007879 | BB35: =MEDIAN!BB3 -> 234729.99 | BC35: =MEDIAN!BC3 -> 41425.407 | BD35: 1.1305203 | BE35: 361474.8 | BF35: 62811.01 | BG35: 6.5104167 | BH35: 8.798148 | BI35: 13.333333 | BJ35: 0.02810916 | BK35: -0.013919505 | BL35: =MEDIAN!BL3 -> 0.15317213 | BM35: 0.23002942 | BN35: =MEDIAN!BN3 -> 0.12036629 | BO35: 0.13748796 | BP35: =MEDIAN!BP3 -> 0.616 | BQ35: =MEDIAN!BQ3 -> 0.208 | BR35: =MEDIAN!BR3 -> 2.299635 | BS35: =MEDIAN!BS3 -> 25 | BT35: =MEDIAN!BT3 -> 15.100125 | BU35: 0.752 | BV35: 0.408 | BW35: 2.8596687 | BX35: 34 | BY35: 28.161354
A36: COBEN_CZCOBEN042 | B36: 18.166129 | C36: 0.44785714 | D36: 10.245 | E36: 3.3929265 | F36: 16.602289 | G36: 19.430823 | H36: 8.4333972 | I36: 0.5994653 | J36: 0.025011305 | K36: 0.099530647 | L36: 6.3725655 | M36: 4.2763059 | N36: 0.51370087 | O36: 0.35993902 | P36: 1.9751259 | Q36: 7.2859721 | R36: 7.2030485 | S36: 4.8703893 | T36: 3.221077 | U36: 0.013094781 | V36: 0.0035561462 | W36: 0.0032312653 | X36: 0.013246853 | Y36: 0.096557522 | Z36: 0.11259759 | AA36: 0.09753319 | AB36: 0.19854977 | AC36: -0.16687012 | AD36: -1.2298431 | AE36: -1.1681366 | AF36: 0.58648682 | AG36: -0.93478394 | AH36: 0.84185791 | AI36: -1.6073151 | AJ36: 0.13291931 | AK36: 37.056 | AL36: 0 | AM36: 0 | AN36: 42.703 | AO36: 0.40284992 | AP36: 0.40687794 | AQ36: 0.16349045 | AR36: 0.037053556 | AS36: 0.25205615 | AT36: 0.1866125 | AU36: 0.27282115 | AV36: 0.31709555 | AW36: 0.22043872 | AX36: 0.17748966 | AY36: 0.59652449 | AZ36: 0.27307867 | BA36: 1.0080859 | BB36: 438656.74 | BC36: 68062.921 | BD36: 1.0395067 | BE36: 262450.39 | BF36: 57375.929 | BG36: 3.5578748 | BH36: 7.8920046 | BI36: -7.3529412 | BJ36: 0.059041371 | BK36: -0.013202797 | BL36: 0.20301885 | BM36: 0.22615156 | BN36: 0.13009384 | BO36: 0.14595274 | BP36: 0.552 | BQ36: 0.216 | BR36: 3.8367546 | BS36: 28 | BT36: 10.69866 | BU36: 0.432 | BV36: 0.128 | BW36: 3.7037387 | BX36: 25 | BY36: 11.129782
A37: COBEN_CZCOBEN044 | B37: 21.179215 | C37: 0.55952381 | D37: 26.716375 | E37: 29.782948 | F37: 30.817567 | G37: 34.353244 | H37: 26.910381 | I37: 0.78801809 | J37: 0.046342903 | K37: 0.019784642 | L37: 0.74671731 | M37: 0.33343822 | N37: 0.29193349 | O37: 0.31638422 | P37: 0.29416539 | Q37: 2.6211602 | R37: 1.5455696 | S37: 1.3208679 | T37: 0.80206921 | U37: 0.0008109056 | V37: 0.00041509428 | W37: 0.0010641228 | X37: 0.0010601416 | Y37: 0.015841259 | Z37: 0.0078048665 | AA37: 0.0086948155 | AB37: 0.020157489 | AC37: -1.684845 | AD37: 0.73634338 | AE37: -0.16619873 | AF37: -0.52151489 | AG37: -0.28807068 | AH37: 0.97583008 | AI37: -0.42274475 | AJ37: 1.379776 | AK37: 0 | AL37: 0 | AM37: 0 | AN37: 0.037 | AO37: 0.60616008 | AP37: 0.62277837 | AQ37: 0.096102578 | AR37: 0.011653187 | AS37: 0.067559887 | AT37: 0.1551999 | AU37: 0.27045361 | AV37: 0.30535418 | AW37: 0.028351186 | AX37: 0.017020405 | AY37: 0.04921918 | AZ37: 0.027019387 | BA37: 1.0598415 | BB37: 379131.9 | BC37: 64094.708 | BD37: 1.1326153 | BE37: 371080.72 | BF37: 68801.457 | BG37: 4.7953964 | BH37: 26.659295 | BI37: -27.419355 | BJ37: 0.063424959 | BK37: -0.0030445344 | BL37: 0.13103871 | BM37: 0.19784572 | BN37: 0.15025676 | BO37: 0.18280186 | BP37: 0.444 | BQ37: 0.104 | BR37: 2.1788361 | BS37: 22 | BT37: 11.09537 | BU37: 0.548 | BV37: 0.116 | BW37: 2.1049862 | BX37: 24 | BY37: 18.414151
A38: COBEN_CZCOBEN046 | B38: 25.433201 | C38: 0.4708 | D38: 14.502062 | E38: 28.470769 | F38: 20.715579 | G38: 32.09247 | H38: 24.961218 | I38: 68.449604 | J38: 0.57756404 | K38: 0.87642103 | L38: 83.455564 | M38: 0.29049748 | N38: 0.26804305 | O38: 0.2546616 | P38: 1.4132184 | Q38: 1.4020574 | R38: 1.5286911 | S38: 1.713047 | T38: 1.7815093 | U38: 0.0010719971 | V38: 0.0009452235 | W38: 0.0014733077 | X38: 0.0011110814 | Y38: 0.012496149 | Z38: 0.0080390291 | AA38: 0.0098695582 | AB38: 0.034927011 | AC38: 1.2355042 | AD38: -1.4902039 | AE38: -0.1321106 | AF38: 1.2955933 | AG38: 1.1347046 | AH38: -3.2642517 | AI38: -0.95571899 | AJ38: 0.28552246 | AK38: 0 | AL38: 0 | AM38: 0 | AN38: 0.069 | AO38: 0.59835108 | AP38: 0.56020912 | AQ38: 0.0081925326 | AR38: 0.046374446 | AS38: 0.065501437 | AT38: 0.020408524 | AU38: 0.25290358 | AV38: 0.27031656 | AW38: 0.0050525565 | AX38: 0.0058637564 | AY38: 0.017246969 | AZ38: 0.02815745 | BA38: 1.049441 | BB38: 635242.02 | BC38: 121133.29 | BD38: 1.1438705 | BE38: 738322.47 | BF38: 135043.25 | BG38: 5.6475904 | BH38: 3.7112546 | BI38: 4.7619048 | BJ38: 0.036821493 | BK38: -0.0052027972 | BL38: 0.15959063 | BM38: 0.19796795 | BN38: 0.10979328 | BO38: 0.15470732 | BP38: 0.536 | BQ38: 0.16 | BR38: 3.2341969 | BS38: 35 | BT38: 13.310173 | BU38: 0.544 | BV38: 0.152 | BW38: 3.0007543 | BX38: 32 | BY38: 18.107909
A39: COBEN_CZCOBEN047 | B39: 21.152427 | C39: 0.61958333 | D39: 16.472562 | E39: 20.100904 | F39: 26.811617 | G39: 31.339339 | H39: 20.133148 | I39: 0.27385987 | J39: 0.0047114559 | K39: 0.0088257187 | L39: 0.78817242 | M39: 0.39739009 | N39: 0.32523725 | O39: 0.32492833 | P39: 0.45648144 | Q39: 2.7099228 | R39: 2.8132613 | S39: 2.0146366 | T39: 1.3211882 | U39: 0.003297535 | V39: 0.0018541696 | W39: 0.0023517777 | X39: 0.0030569434 | Y39: 0.039281162 | Z39: 0.017456493 | AA39: 0.014540627 | AB39: 0.042186208 | AC39: 0.39154053 | AD39: 0.14601135 | AE39: -0.78253174 | AF39: 0.27560425 | AG39: -0.81752014 | AH39: 0.11849976 | AI39: -0.89476013 | AJ39: 0.77095032 | AK39: 0 | AL39: 0 | AM39: 0 | AN39: 0 | AO39: 0.59020234 | AP39: 0.54803609 | AQ39: 0.26879417 | AR39: 0.042820181 | AS39: 0.05554221 | AT39: 0.23352787 | AU39: 0.2948002 | AV39: 0.29093957 | AW39: 0.15549653 | AX39: 0.025079255 | AY39: 0.092834575 | AZ39: 0.13983283 | BA39: 1.0999602 | BB39: 506748.12 | BC39: 84817.443 | BD39: 1.1311522 | BE39: 538791.52 | BF39: 96716.863 | BG39: 5.013369 | BH39: 5.4163396 | BI39: -3.5714286 | BJ39: 0.029874688 | BK39: -0.0016442688 | BL39: 0.20094533 | BM39: 0.25158469 | BN39: 0.11492369 | BO39: 0.1478337 | BP39: 0.544 | BQ39: 0.148 | BR39: 2.1746649 | BS39: 24 | BT39: 10.038102 | BU39: 0.752 | BV39: 0.232 | BW39: 2.256631 | BX39: 29 | BY39: 19.717952
A40: COBEN_CZCOBEN048 | B40: 18.485223 | C40: 0.69823529 | D40: 13.070063 | E40: 26.157462 | F40: 30.238255 | G40: 34.580971 | H40: 25.408764 | I40: 1.7980522 | J40: 0.030190293 | K40: 0.016098577 | L40: 1.6909875 | M40: 0.28522146 | N40: 0.23811538 | O40: 0.30626539 | P40: 0.4630883 | Q40: 1.3327886 | R40: 1.6226282 | S40: 3.0266349 | T40: 1.025113 | U40: 0.002168154 | V40: 0.0005421812 | W40: 0.00083251592 | X40: 0.0017018579 | Y40: 0.014469169 | Z40: 0.011298096 | AA40: 0.012700975 | AB40: 0.014187458 | AC40: -0.50267029 | AD40: -0.79559326 | AE40: 0.55505371 | AF40: 1.679184 | AG40: -1.0962372 | AH40: -0.92910767 | AI40: -0.46803284 | AJ40: 0.5826416 | AK40: 0 | AL40: 0 | AM40: 0 | AN40: 0.077 | AO40: 0.51844088 | AP40: 0.56997081 | AQ40: 0.029262278 | AR40: 0.013772505 | AS40: 0.052058494 | AT40: 0.088243643 | AU40: 0.28103363 | AV40: 0.30040222 | AW40: 0.012667319 | AX40: 0.0085955186 | AY40: 0.10967373 | AZ40: 0.031516316 | BA40: 1.1505283 | BB40: 522910.03 | BC40: 90515.459 | BD40: 1.0986486 | BE40: 385384.63 | BF40: 70602.078 | BG40: 5.1510989 | BH40: 3.7457459 | BI40: 7.1428571 | BJ40: 0.043016802 | BK40: -0.0026325123 | BL40: 0.23248439 | BM40: 0.21698356 | BN40: 0.094907455 | BO40: 0.16335024 | BP40: 0.772 | BQ40: 0.388 | BR40: 2.721555 | BS40: 29 | BT40: 27.466986 | BU40: 0.552 | BV40: 0.176 | BW40: 2.326781 | BX40: 24 | BY40: 17.625146
...

Sheet MEDIAN
B1: RR_TSK2 | C1: IPAmean_TSK2 | D1: MPT_TSK6 | E1: HNR_TSK3 | F1: HNR_TSK4 | G1: HNR_TSK5 | H1: HNR_TSK6 | I1: HRF_TSK3 | J1: HRF_TSK4 | K1: HRF_TSK5 | L1: HRF_TSK6 | M1: Jitter_TSK3 | N1: Jitter_TSK4 | O1: Jitter_TSK5 | P1: Jitter_TSK6 | Q1: Shimmer_TSK3 | R1: Shimmer_TSK4 | S1: Shimmer_TSK5 | T1: Shimmer_TSK6 | U1: PPQ_TSK3 | V1: PPQ_TSK4 | W1: PPQ_TSK5 | X1: PPQ_TSK6 | Y1: APQ_TSK3 | Z1: APQ_TSK4 | AA1: APQ_TSK5 | AB1: APQ_TSK6 | AC1: DF0_TSK3 | AD1: DF0_TSK4 | AE1: DF0_TSK5 | AF1: DF0_TSK6 | AG1: DDF0_TSK3 | AH1: DDF0_TSK4 | AI1: DDF0_TSK5 | AJ1: DDF0_TSK6 | AK1: DUV_TSK3 | AL1: DUV_TSK4 | AM1: DUV_TSK5 | AN1: DUV_TSK6 | AO1: RelF1SD_TSK1 | AP1: RelF1SD_TSK2 | AQ1: RelF1SD_TSK3 | AR1: RelF1SD_TSK4 | AS1: RelF1SD_TSK5 | AT1: RelF1SD_TSK6 | AU1: RelF2SD_TSK1 | AV1: RelF2SD_TSK2 | AW1: RelF2SD_TSK3 | AX1: RelF2SD_TSK4 | AY1: RelF2SD_TSK5 | AZ1: RelF2SD_TSK6 | BA1: VAI_TSK1 | BB1: VSHA_TSK1 | BC1: AAVS_TSK1 | BD1: VAI_TSK2 | BE1: VSHA_TSK2 | BF1: AAVS_TSK2 | BG1: PR_TSK7 | BH1: COV_TSK7 | BI1: PA_TSK7 | BJ1: RI_TSK7 | BK1: RA_TSK7 | BL1: RelF0SD_TSK1 | BM1: RelF0SD_TSK2 | BN1: RelSE0SD_TSK1 | BO1: RelSE0SD_TSK2 | BP1: DurMED_TSK1 | BQ1: DurMAD_TSK1 | BR1: SPIR_TSK1 | BS1: pause_n_TSK1 | BT1: pause_ratio_TSK1 | BU1: DurMED_TSK2 | BV1: DurMAD_TSK2 | BW1: SPIR_TSK2 | BX1: pause_n_TSK2 | BY1: pause_ratio_TSK2
