Workbook

Sheet Sheet1
A1: Project | B1: Path | C1: Filename | D1: #id | E1: #personalID | F1: Subject | G1: #sex | H1: gender | I1: Category | J1: age | K1: MOCA | L1: education type | M1: education length | N1: memory z-score | O1: visuo-spatial z-score | P1: attention z-score | Q1: executive function z-score | R1: GDS
A2: COBEN | B2: /CEITEC/speech | C2: COBEN_ACOUSTIC_BB_AD16.wav | D2: CZCOBEN000 | E2: CZCOBENAD2009 | F2: =A2&"_"&D2 -> COBEN_CZCOBEN000 | G2: M | H2: =IF(G2="M",0,IF(G2="F",1,"")) -> 0 | I2: MCI-AD | J2: 74.16564 | K2: 23 | L2: 4 | M2: 18 | N2: -2.08 | O2: -0.25 | P2: -0.35 | Q2: -0.9 | R2: 0
A3: COBEN | B3: /CEITEC/speech | C3: COBEN_ACOUSTIC_PK_HC02.wav | D3: CZCOBEN002 | E3: CZCOBENK2002 | F3: =A3&"_"&D3 -> COBEN_CZCOBEN002 | G3: M | H3: =IF(G3="M",0,IF(G3="F",1,"")) -> 0 | I3: HC | J3: 60.156057 | K3: 27 | L3: 4 | M3: 17 | N3: 1.21 | O3: 0.15 | P3: -0.58 | Q3: -0.49 | R3: 2
A4: COBEN | B4: /CEITEC/speech | C4: COBEN_ACOUSTIC_VS_HC05.wav | D4: CZCOBEN004 | E4: CZCOBENK1005 | F4: =A4&"_"&D4 -> COBEN_CZCOBEN004 | G4: F | H4: =IF(G4="M",0,IF(G4="F",1,"")) -> 1 | I4: HC | J4: 60.714579 | K4: 27 | L4: 3 | M4: 13 | N4: 1.18 | O4: 0.58 | P4: 0.33 | Q4: 0.23 | R4: 4
A5: COBEN | B5: /CEITEC/speech | C5: COBEN_ACOUSTIC_MN_HC06.wav | D5: CZCOBEN005 | E5: CZCOBENK1006 | F5: =A5&"_"&D5 -> COBEN_CZCOBEN005 | G5: F | H5: =IF(G5="M",0,IF(G5="F",1,"")) -> 1 | I5: HC | J5: 59.863107 | K5: 27 | L5: 3 | M5: 15 | N5: 0.99 | O5: -0.77 | P5: 0.18 | Q5: 1.56 | R5: 4
A6: COBEN | B6: /CEITEC/speech | C6: COBEN_ACOUSTIC_VP_HC09.wav | D6: CZCOBEN007 | E6: CZCOBENK2009 | F6: =A6&"_"&D6 -> COBEN_CZCOBEN007 | G6: M | H6: =IF(G6="M",0,IF(G6="F",1,"")) -> 0 | I6: HC | J6: 66.099932 | K6: 27 | L6: 4 | M6: 17 | N6: 1.75 | O6: 1.08 | P6: 0.1 | Q6: 0.39 | R6: 0
A7: COBEN | B7: /CEITEC/speech | C7: COBEN_ACOUSTIC_MH_HC10.wav | D7: CZCOBEN008 | E7: CZCOBENK1010 | F7: =A7&"_"&D7 -> COBEN_CZCOBEN008 | G7: F | H7: =IF(G7="M",0,IF(G7="F",1,"")) -> 1 | I7: HC | J7: 66.212183 | K7: 27 | L7: 4 | M7: 16 | N7: 1.05 | O7: 0.15 | P7: 0.44 | Q7: 0.33 | R7: 0
A8: COBEN | B8: /CEITEC/speech | C8: COBEN_ACOUSTIC_HZ_HC13.wav | D8: CZCOBEN009 | E8: CZCOBENK1013 | F8: =A8&"_"&D8 -> COBEN_CZCOBEN009 | G8: F | H8: =IF(G8="M",0,IF(G8="F",1,"")) -> 1 | I8: HC | J8: 64.51 | K8: 25 | L8: 4 | M8: 17 | N8: 0.89 | O8: 0.58 | P8: 0.21 | Q8: 1.14 | R8: 0
A9: COBEN | B9: /CEITEC/speech | C9: COBEN_ACOUSTIC_JJ_HC14.wav | D9: CZCOBEN010 | E9: CZCOBENK2014 | F9: =A9&"_"&D9 -> COBEN_CZCOBEN010 | G9: M | H9: =IF(G9="M",0,IF(G9="F",1,"")) -> 0 | I9: HC | J9: 75.616701 | K9: 27 | L9: 4 | M9: 17 | N9: 2.09 | O9: 0.15 | P9: 0.41 | Q9: 0.49 | R9: 2
A10: COBEN | B10: /CEITEC/speech | C10: COBEN_ACOUSTIC_JS_HC18.wav | D10: CZCOBEN011 | E10: CZCOBENK1018 | F10: =A10&"_"&D10 -> COBEN_CZCOBEN011 | G10: F | H10: =IF(G10="M",0,IF(G10="F",1,"")) -> 1 | I10: HC | J10: 63.611225 | K10: 27 | L10: 3 | M10: 13 | N10: -0.16 | O10: 0.15 | P10: 0.43 | Q10: -0.67 | R10: 2
A11: COBEN | B11: /CEITEC/speech | C11: COBEN_ACOUSTIC_RL_HC20.wav | D11: CZCOBEN012 | E11: CZCOBENK1020 | F11: =A11&"_"&D11 -> COBEN_CZCOBEN012 | G11: M | H11: =IF(G11="M",0,IF(G11="F",1,"")) -> 0 | I11: HC | J11: 62.047912 | K11: 27 | L11: 4 | M11: 18 | N11: 1.58 | O11: 0.15 | P11: -0.44 | Q11: -0.26 | R11: 0
A12: COBEN | B12: /CEITEC/speech | C12: COBEN_ACOUSTIC_HJ_HC21.wav | D12: CZCOBEN013 | E12: CZCOBENK1021 | F12: =A12&"_"&D12 -> COBEN_CZCOBEN013 | G12: F | H12: =IF(G12="M",0,IF(G12="F",1,"")) -> 1 | I12: HC | J12: 70.877481 | K12: 23 | L12: 3 | M12: 13 | N12: -0.68 | O12: -0.25 | P12: -0.36 | Q12: -1.59 | R12: 6
A13: COBEN | B13: /CEITEC/speech | C13: COBEN_ACOUSTIC_JB_HC22.wav | D13: CZCOBEN014 | E13: CZCOBENK1022 | F13: =A13&"_"&D13 -> COBEN_CZCOBEN014 | G13: F | H13: =IF(G13="M",0,IF(G13="F",1,"")) -> 1 | I13: HC | J13: 67.422313 | K13: 25 | L13: 4 | M13: 19 | N13: 0.86 | O13: 0.58 | P13: 0.39 | Q13: 0.68 | R13: 10
... A55: COBEN | B55: /CEITEC/speech | C55: COBEN_ACOUSTIC_MJ_HCD2.wav | D55: CZCOBEN065 | E55: CZCOBENK10D2 | F55: =A55&"_"&D55 -> COBEN_CZCOBEN065 | G55: F | H55: =IF(G55="M",0,IF(G55="F",1,"")) -> 1 | I55: HC | J55: 62.516085 | K55: 25 | L55: 4 | M55: 17 | N55: 0.86 | O55: 0.15 | P55: -0.74 | Q55: -0.08 | R55: 6
A56: HIDI LONG | B56: /CEITEC/speech/HIDI_LONG | C56: HIDI_LONG_neMRI_JJ_pred_stim.wav | D56: 100 | E56: AZV2P2001 | F56: =A56&"_"&D56 -> HIDI LONG_100 | G56: F | H56: =IF(G56="M",0,IF(G56="F",1,"")) -> 1 | I56: PD-MCI | J56: 71.487671 | K56: =median!C$3 -> 23 | L56: 4 | M56: 18 | N56: =median!F$3 -> -2.08 | O56: =median!G$3 -> -0.25 | P56: =median!H$3 -> -0.35 | Q56: =median!I$3 -> -0.9 | R56: =median!J$3 -> 0
A57: HIDI LONG | B57: /CEITEC/speech/HIDI_LONG | C57: HIDI_LONG_neMRI_KM_pred_stim.wav | D57: 1000 | E57: AZV2P2003 | F57: =A57&"_"&D57 -> HIDI LONG_1000 | G57: F | H57: =IF(G57="M",0,IF(G57="F",1,"")) -> 1 | I57: PD-MCI | J57: 60.227397 | K57: 20 | L57: 3 | M57: 12 | N57: -0.68 | O57: =median!G$3 -> -0.25 | P57: -0.12 | Q57: -0.53 | R57: 8
A58: HIDI LONG | B58: /CEITEC/speech/HIDI_LONG | C58: HIDI_LONG_neMRI_KK_pred_stim.wav | D58: 1100 | E58: AZV2P1008 | F58: =A58&"_"&D58 -> HIDI LONG_1100 | G58: M | H58: =IF(G58="M",0,IF(G58="F",1,"")) -> 0 | I58: PD-MCI | J58: 73.309589 | K58: 27 | L58: 4 | M58: 18 | N58: 0.68 | O58: =median!G$3 -> -0.25 | P58: -2.19 | Q58: -0.98 | R58: 10
A59: HIDI LONG | B59: /CEITEC/speech/HIDI_LONG | C59: HIDI_LONG_neMRI_PVE_pred_stim.wav | D59: 1200 | E59: AZV2P1009 | F59: =A59&"_"&D59 -> HIDI LONG_1200 | G59: M | H59: =IF(G59="M",0,IF(G59="F",1,"")) -> 0 | I59: PD-MCI | J59: 72.471233 | K59: =median!C$3 -> 23 | L59: =median!D$3 -> 4 | M59: =median!E$3 -> 18 | N59: =median!F$3 -> -2.08 | O59: =median!G$3 -> -0.25 | P59: =median!H$3 -> -0.35 | Q59: =median!I$3 -> -0.9 | R59: =median!J$3 -> 0
A60: HIDI LONG | B60: /CEITEC/speech/HIDI_LONG | C60: HIDI_LONG_neMRI_ZW_pred_stim.wav | D60: 1300 | E60: AZV2P1010 | F60: =A60&"_"&D60 -> HIDI LONG_1300 | G60: M | H60: =IF(G60="M",0,IF(G60="F",1,"")) -> 0 | I60: PD-MCI | J60: 70.509589 | K60: =median!C$3 -> 23 | L60: =median!D$3 -> 4 | M60: =median!E$3 -> 18 | N60: =median!F$3 -> -2.08 | O60: =median!G$3 -> -0.25 | P60: =median!H$3 -> -0.35 | Q60: =median!I$3 -> -0.9 | R60: =median!J$3 -> 0
A61: HIDI LONG | B61: /CEITEC/speech/HIDI_LONG | C61: HIDI_LONG_neMRI_RP_pred_stim.wav | D61: 1500 | E61: AZV2P1012 | F61: =A61&"_"&D61 -> HIDI LONG_1500 | G61: M | H61: =IF(G61="M",0,IF(G61="F",1,"")) -> 0 | I61: PD-MCI | J61: 72.69863 | K61: 25 | L61: 3 | M61: 13 | N61: 0.17 | O61: 0.37 | P61: -1.22 | Q61: -0.98 | R61: 6
A62: HIDI LONG | B62: /CEITEC/speech/HIDI_LONG | C62: HIDI_LONG_neMRI_JKRU_pred_stim.wav | D62: 1600 | E62: AZV2P2004 | F62: =A62&"_"&D62 -> HIDI LONG_1600 | G62: F | H62: =IF(G62="M",0,IF(G62="F",1,"")) -> 1 | I62: PD-MCI | J62: 79.627397 | K62: 23 | L62: 3 | M62: =median!E$3 -> 18 | N62: 0.63 | O62: -0.42 | P62: -0.16 | Q62: -0.13 | R62: 20
A63: HIDI LONG | B63: /CEITEC/speech/HIDI_LONG | C63: HIDI_LONG_neMRI_DM_pred_stim.wav | D63: 1700 | E63: AZV2P1013 | F63: =A63&"_"&D63 -> HIDI LONG_1700 | G63: M | H63: =IF(G63="M",0,IF(G63="F",1,"")) -> 0 | I63: PD-NC | J63: 70.312329 | K63: 29 | L63: 3 | M63: 13 | N63: 2.23 | O63: 1.25 | P63: 0.02 | Q63: 0.94 | R63: 6
A64: HIDI LONG | B64: /CEITEC/speech/HIDI_LONG | C64: HIDI_LONG_neMRI_JMA_pred_stim.wav | D64: 1800 | E64: AZV2P1014 | F64: =A64&"_"&D64 -> HIDI LONG_1800 | G64: M | H64: =IF(G64="M",0,IF(G64="F",1,"")) -> 0 | I64: PD-MCI | J64: 61.005479 | K64: 25 | L64: 4 | M64: 17 | N64: -1.54 | O64: -0.31 | P64: -0.83 | Q64: -1.11 | R64: 6
A65: HIDI LONG | B65: /CEITEC/speech/HIDI_LONG | C65: HIDI_LONG_neMRI_RR_pred_stim.wav | D65: 1900 | E65: AZV2P1015 | F65: =A65&"_"&D65 -> HIDI LONG_1900 | G65: M | H65: =IF(G65="M",0,IF(G65="F",1,"")) -> 0 | I65: PD-MCI | J65: 77.493151 | K65: 27 | L65: 4 | M65: 16 | N65: -1.38 | O65: 0.06 | P65: -1 | Q65: -0.28 | R65: 0
A66: HIDI LONG | B66: /CEITEC/speech/HIDI_LONG | C66: HIDI_LONG_neMRI_ON_pred_stim.wav | D66: 200 | E66: AZV2P1001 | F66: =A66&"_"&D66 -> HIDI LONG_200 | G66: M | H66: =IF(G66="M",0,IF(G66="F",1,"")) -> 0 | I66: PD-MCI | J66: 79.364384 | K66: 22 | L66: 3 | M66: 12 | N66: -0.46 | O66: 0.37 | P66: -1.35 | Q66: -1.46 | R66: 6
A67: HIDI LONG | B67: /CEITEC/speech/HIDI_LONG | C67: HIDI_LONG_neMRI_MK_pred_stim.wav | D67: 2000 | E67: AZV2P2005 | F67: =A67&"_"&D67 -> HIDI LONG_2000 | G67: F | H67: =IF(G67="M",0,IF(G67="F",1,"")) -> 1 | I67: PD-MCI | J67: 76.652055 | K67: 23 | L67: 4 | M67: 18 | N67: -0.01 | O67: 0.78 | P67: -1.28 | Q67: -1.43 | R67: 8
A68: HIDI LONG | B68: /CEITEC/speech/HIDI_LONG | C68: HIDI_LONG_neMRI_ZT_pred_stim.wav | D68: 2100 | E68: AZV2P1016 | F68: =A68&"_"&D68 -> HIDI LONG_2100 | G68: M | H68: =IF(G68="M",0,IF(G68="F",1,"")) -> 0 | I68: PD-MCI | J68: 60.712329 | K68: 27 | L68: 4 | M68: 18 | N68: 0.48 | O68: 0.68 | P68: -1.07 | Q68: 0.31 | R68: 12
A69: HIDI LONG | B69: /CEITEC/speech/HIDI_LONG | C69: HIDI_LONG_neMRI_KKI_pred_stim.wav | D69: 2200 | E69: AZV2P1017 | F69: =A69&"_"&D69 -> HIDI LONG_2200 | G69: M | H69: =IF(G69="M",0,IF(G69="F",1,"")) -> 0 | I69: PD-MCI | J69: 66.810959 | K69: 27 | L69: 3 | M69: 13 | N69: 0.33 | O69: -0.28 | P69: -0.93 | Q69: -0.72 | R69: 6
A70: HIDI LONG | B70: /CEITEC/speech/HIDI_LONG | C70: HIDI_LONG_neMRI_MKY_pred_stim.wav | D70: 2400 | E70: AZV2P1019 | F70: =A70&"_"&D70 -> HIDI LONG_2400 | G70: M | H70: =IF(G70="M",0,IF(G70="F",1,"")) -> 0 | I70: PD-MCI | J70: 72.810959 | K70: 22 | L70: 3 | M70: 13 | N70: 0.94 | O70: -0.32 | P70: -0.8 | Q70: -0.6 | R70: 2
A71: HIDI LONG | B71: /CEITEC/speech/HIDI_LONG | C71: HIDI_LONG_neMRI_KJ_pred_stim.wav | D71: 2500 | E71: AZV2P1020 | F71: =A71&"_"&D71 -> HIDI LONG_2500 | G71: M | H71: =IF(G71="M",0,IF(G71="F",1,"")) -> 0 | I71: PD-MCI | J71: 81.227397 | K71: 22 | L71: 3 | M71: 13 | N71: 0.49 | O71: -0.59 | P71: -1.2 | Q71: 0 | R71: 8
A72: HIDI LONG | B72: /CEITEC/speech/HIDI_LONG | C72: HIDI_LONG_neMRI_MP_pred_stim.wav | D72: 2600 | E72: AZV2P2006 | F72: =A72&"_"&D72 -> HIDI LONG_2600 | G72: F | H72: =IF(G72="M",0,IF(G72="F",1,"")) -> 1 | I72: PD-MCI | J72: 73.10137 | K72: 27 | L72: 4 | M72: 18 | N72: -0.18 | O72: -0.38 | P72: -1.77 | Q72: -1.48 | R72: 10
A73: HIDI LONG | B73: /CEITEC/speech/HIDI_LONG | C73: HIDI_LONG_neMRI_JC_pred_stim.wav | D73: 2700 | E73: AZV2P1021 | F73: =A73&"_"&D73 -> HIDI LONG_2700 | G73: M | H73: =IF(G73="M",0,IF(G73="F",1,"")) -> 0 | I73: PD-MCI | J73: 77.80274 | K73: 22 | L73: 3 | M73: 13 | N73: -1.93 | O73: -0.84 | P73: -2.15 | Q73: -1.56 | R73: 20
A74: HIDI LONG | B74: /CEITEC/speech/HIDI_LONG | C74: HIDI_LONG_neMRI_PH_pred_stim.wav | D74: 2800 | E74: AZV2P1022 | F74: =A74&"_"&D74 -> HIDI LONG_2800 | G74: M | H74: =IF(G74="M",0,IF(G74="F",1,"")) -> 0 | I74: PD-NC | J74: 80.920548 | K74: 23 | L74: 4 | M74: 16 | N74: 1.97 | O74: 1.25 | P74: 0.12 | Q74: 0.98 | R74: 2
A75: HIDI LONG | B75: /CEITEC/speech/HIDI_LONG | C75: HIDI_LONG_neMRI_HH_pred_stim.wav | D75: 2900 | E75: AZV2P2007 | F75: =A75&"_"&D75 -> HIDI LONG_2900 | G75: F | H75: =IF(G75="M",0,IF(G75="F",1,"")) -> 1 | I75: PD-MCI | J75: 74.50137 | K75: 29 | L75: 4 | M75: 17 | N75: 1.9 | O75: 0.89 | P75: -0.59 | Q75: -1.28 | R75: 6
A76: HIDI LONG | B76: /CEITEC/speech/HIDI_LONG | C76: HIDI_LONG_neMRI_JR_pred_stim.wav | D76: 300 | E76: AZV2P1002 | F76: =A76&"_"&D76 -> HIDI LONG_300 | G76: M | H76: =IF(G76="M",0,IF(G76="F",1,"")) -> 0 | I76: PD-MCI | J76: 53.005479 | K76: =median!C$3 -> 23 | L76: 3 | M76: 13 | N76: =median!F$3 -> -2.08 | O76: =median!G$3 -> -0.25 | P76: =median!H$3 -> -0.35 | Q76: =median!I$3 -> -0.9 | R76: =median!J$3 -> 0
A77: HIDI LONG | B77: /CEITEC/speech/HIDI_LONG | C77: HIDI_LONG_neMRI_VV_pred_stim.wav | D77: 3000 | E77: AZV2P1023 | F77: =A77&"_"&D77 -> HIDI LONG_3000 | G77: M | H77: =IF(G77="M",0,IF(G77="F",1,"")) -> 0 | I77: PD-MCI | J77: 68.183562 | K77: =median!C$3 -> 23 | L77: =median!D$3 -> 4 | M77: =median!E$3 -> 18 | N77: =median!F$3 -> -2.08 | O77: =median!G$3 -> -0.25 | P77: =median!H$3 -> -0.35 | Q77: =median!I$3 -> -0.9 | R77: =median!J$3 -> 0
A78: HIDI LONG | B78: /CEITEC/speech/HIDI_LONG | C78: HIDI_LONG_neMRI_LK_pred_stim.wav | D78: 3100 | E78: AZV2P1024 | F78: =A78&"_"&D78 -> HIDI LONG_3100 | G78: M | H78: =IF(G78="M",0,IF(G78="F",1,"")) -> 0 | I78: PD-MCI | J78: 73.238356 | K78: 25 | L78: 4 | M78: 18 | N78: 0.13 | O78: =median!G$3 -> -0.25 | P78: 0.01 | Q78: -0.25 | R78: 2
A79: HIDI LONG | B79: /CEITEC/speech/HIDI_LONG | C79: HIDI_LONG_neMRI_JB_pred_stim.wav | D79: 3200 | E79: AZV2P2008 | F79: =A79&"_"&D79 -> HIDI LONG_3200 | G79: F | H79: =IF(G79="M",0,IF(G79="F",1,"")) -> 1 | I79: PD-MCI | J79: 84.142466 | K79: 22 | L79: =median!D$3 -> 4 | M79: 3 | N79: -0.52 | O79: -0.5 | P79: -0.83 | Q79: -0.39 | R79: 18
A80: HIDI LONG | B80: /CEITEC/speech/HIDI_LONG | C80: HIDI_LONG_neMRI_IP_pred_stim.wav | D80: 3300 | E80: AZV2P2009 | F80: =A80&"_"&D80 -> HIDI LONG_3300 | G80: F | H80: =IF(G80="M",0,IF(G80="F",1,"")) -> 1 | I80: PD-MCI | J80: 78.282192 | K80: 22 | L80: =median!D$3 -> 4 | M80: 4 | N80: -1.12 | O80: 0.37 | P80: -0.08 | Q80: -0.17 | R80: 0
A81: HIDI LONG | B81: /CEITEC/speech/HIDI_LONG | C81: HIDI_LONG_neMRI_PV_pred_stim.wav | D81: 400 | E81: AZV2P1003 | F81: =A81&"_"&D81 -> HIDI LONG_400 | G81: M | H81: =IF(G81="M",0,IF(G81="F",1,"")) -> 0 | I81: PD-MCI | J81: 75.443836 | K81: 23 | L81: 4 | M81: 18 | N81: =median!F$3 -> -2.08 | O81: =median!G$3 -> -0.25 | P81: =median!H$3 -> -0.35 | Q81: =median!I$3 -> -0.9 | R81: =median!J$3 -> 0
...

Sheet median
B1: age | C1: MOCA | D1: education type | E1: education length | F1: memory z-score | G1: visuo-spatial z-score | H1: attention z-score | I1: executive function z-score | J1: GDS
A2: formula | B2: =MEDIAN(IF(ISNUMBER(Sheet1!J2),Sheet1!J2)) -> 74.16564 | C2: =MEDIAN(IF(ISNUMBER(Sheet1!K2),Sheet1!K2)) -> 23 | D2: =MEDIAN(IF(ISNUMBER(Sheet1!L2),Sheet1!L2)) -> 4 | E2: =MEDIAN(IF(ISNUMBER(Sheet1!M2),Sheet1!M2)) -> 18 | F2: =MEDIAN(IF(ISNUMBER(Sheet1!N2),Sheet1!N2)) -> -2.08 | G2: =MEDIAN(IF(ISNUMBER(Sheet1!O2),Sheet1!O2)) -> -0.25 | H2: =MEDIAN(IF(ISNUMBER(Sheet1!P2),Sheet1!P2)) -> -0.35 | I2: =MEDIAN(IF(ISNUMBER(Sheet1!Q2),Sheet1!Q2)) -> -0.9 | J2: =MEDIAN(IF(ISNUMBER(Sheet1!R2),Sheet1!R2)) -> 0
B3: 74.16564 | C3: 23 | D3: 4 | E3: 18 | F3: -2.08 | G3: -0.25 | H3: -0.35 | I3: -0.9 | J3: 0

Sheet stats
B2: Class | C2: Count
B3: PD-MCI | C3: =COUNTIF(Sheet1!I2:I415, "PD-MCI") -> 93
B4: HC | C4: =COUNTIF(Sheet1!I2:I415, "HC") -> 175
B5: MCI-LB | C5: =COUNTIF(Sheet1!I2:I415, "MCI-LB") -> 79
B6: MCI-AD | C6: =COUNTIF(Sheet1!I2:I415, "MCI-AD") -> 62
B7: PD-NC | C7: =COUNTIF(Sheet1!I2:I415, "PD-NC") -> 5
B8: Total | C8: =SUM(C3:C7) -> 414
B11: # Unique: | C11: =IFERROR(__xludf.DUMMYFUNCTION("COUNTUNIQUE(Sheet1!I2:I415)"),5) -> 5
