Workbook

Sheet Linguistic_parameters2
A1: Subject | B1: Lex_total_tokens | C1: Lex_unique_types | D1: Lex_TTR | E1: Lex_repetition_ratio | F1: Lex_hapax_ratio | G1: Lex_HDD | H1: Sem_personal_ratio | I1: Sem_vague_ratio | J1: Sem_personal_count | K1: Sem_vague_count | L1: Sem_semantic_category_count | M1: Sem_content_density | N1: Sem_n_content | O1: Sem_n_tokens | P1: Syn_num_sent | Q1: Syn_MLU | R1: Syn_sub_per_sent | S1: Syn_total_sub | T1: Syn_hes | U1: Syn_hes_per_min
A2: COBEN_CZCOBEN000 | B2: 122 | C2: 95 | D2: 0.77868852 | E2: 0.3852459 | F2: 0.78947368 | G2: 0.908778 | H2: 0.016393443 | I2: 0.016393443 | J2: 2 | K2: 2 | L2: 4 | M2: 0.54918033 | N2: 67 | O2: 122 | P2: 8 | Q2: 15.25 | R2: 1.875 | S2: 15 | T2: 0 | U2: 0
A3: COBEN_CZCOBEN002 | B3: 227 | C3: 140 | D3: 0.61674009 | E3: 0.52863436 | F3: 0.76428571 | G3: 0.8448915 | H3: 0.0044052863 | I3: 0.0044052863 | J3: 1 | K3: 1 | L3: 2 | M3: 0.61674009 | N3: 140 | O3: 227 | P3: 10 | Q3: 22.7 | R3: 2.1 | S3: 21 | T3: 0 | U3: 0
A4: COBEN_CZCOBEN004 | B4: 171 | C4: 111 | D4: 0.64912281 | E4: 0.47953216 | F4: 0.8018018 | G4: 0.82932859 | H4: 0.046783626 | I4: 0 | J4: 8 | K4: 0 | L4: 4 | M4: 0.51764706 | N4: 88 | O4: 170 | P4: 13 | Q4: 13.153846 | R4: 1.5384615 | S4: 20 | T4: 0 | U4: 0
A5: COBEN_CZCOBEN005 | B5: 175 | C5: 131 | D5: 0.74857143 | E5: 0.36571429 | F5: 0.84732824 | G5: 0.89957289 | H5: 0.028571429 | I5: 0.011428571 | J5: 5 | K5: 2 | L5: 4 | M5: 0.55747126 | N5: 97 | O5: 174 | P5: 13 | Q5: 13.461538 | R5: 1.9230769 | S5: 25 | T5: 0 | U5: 0
A6: COBEN_CZCOBEN007 | B6: 230 | C6: 136 | D6: 0.59130435 | E6: 0.53913043 | F6: 0.77941176 | G6: 0.8177618 | H6: 0.034782609 | I6: 0.017391304 | J6: 8 | K6: 4 | L6: 4 | M6: 0.46086957 | N6: 106 | O6: 230 | P6: 6 | Q6: 38.333333 | R6: 6 | S6: 36 | T6: 1 | U6: 0.59754967
A7: COBEN_CZCOBEN008 | B7: 197 | C7: 148 | D7: 0.75126904 | E7: 0.38071066 | F7: 0.82432432 | G7: 0.91326999 | H7: 0.015228426 | I7: 0.015228426 | J7: 3 | K7: 3 | L7: 4 | M7: 0.61928934 | N7: 122 | O7: 197 | P7: 10 | Q7: 19.7 | R7: 2.2 | S7: 22 | T7: 0 | U7: 0
A8: COBEN_CZCOBEN009 | B8: 201 | C8: 131 | D8: 0.65174129 | E8: 0.48258706 | F8: 0.79389313 | G8: 0.85867543 | H8: 0.014925373 | I8: 0.024875622 | J8: 3 | K8: 5 | L8: 3 | M8: 0.48258706 | N8: 97 | O8: 201 | P8: 26 | Q8: 7.7307692 | R8: 0.76923077 | S8: 20 | T8: 0 | U8: 0
A9: COBEN_CZCOBEN010 | B9: 180 | C9: 126 | D9: 0.7 | E9: 0.46111111 | F9: 0.76984127 | G9: 0.89355533 | H9: 0.011111111 | I9: 0.044444444 | J9: 2 | K9: 8 | L9: 3 | M9: 0.53038674 | N9: 96 | O9: 181 | P9: 12 | Q9: 15 | R9: 2.25 | S9: 27 | T9: 0 | U9: 0
A10: COBEN_CZCOBEN011 | B10: 273 | C10: 156 | D10: 0.57142857 | E10: 0.56043956 | F10: 0.76923077 | G10: 0.83238279 | H10: 0.014652015 | I10: 0.025641026 | J10: 4 | K10: 7 | L10: 4 | M10: 0.44727273 | N10: 123 | O10: 275 | P10: 10 | Q10: 27.3 | R10: 4.8 | S10: 48 | T10: 0 | U10: 0
A11: COBEN_CZCOBEN012 | B11: 133 | C11: 94 | D11: 0.70676692 | E11: 0.42857143 | F11: 0.80851064 | G11: 0.85547534 | H11: 0 | I11: 0.015037594 | J11: 0 | K11: 2 | L11: 2 | M11: 0.53731343 | N11: 72 | O11: 134 | P11: 8 | Q11: 16.625 | R11: 2 | S11: 16 | T11: 0 | U11: 0
A12: COBEN_CZCOBEN013 | B12: 194 | C12: 131 | D12: 0.67525773 | E12: 0.48969072 | F12: 0.75572519 | G12: 0.88029092 | H12: 0.020618557 | I12: 0.015463918 | J12: 4 | K12: 3 | L12: 4 | M12: 0.52820513 | N12: 103 | O12: 195 | P12: 6 | Q12: 32.333333 | R12: 4.1666667 | S12: 25 | T12: 0 | U12: 0
A13: COBEN_CZCOBEN014 | B13: 165 | C13: 121 | D13: 0.73333333 | E13: 0.38787879 | F13: 0.83471074 | G13: 0.88771638 | H13: 0.012121212 | I13: 0.03030303 | J13: 2 | K13: 5 | L13: 3 | M13: 0.56626506 | N13: 94 | O13: 166 | P13: 8 | Q13: 20.625 | R13: 3 | S13: 24 | T13: 0 | U13: 0
A14: COBEN_CZCOBEN015 | B14: 256 | C14: 171 | D14: 0.66796875 | E14: 0.484375 | F14: 0.77192982 | G14: 0.88783061 | H14: 0.015625 | I14: 0.01953125 | J14: 4 | K14: 5 | L14: 4 | M14: 0.51750973 | N14: 133 | O14: 257 | P14: 8 | Q14: 32 | R14: 4.625 | S14: 37 | T14: 0 | U14: 0
A15: COBEN_CZCOBEN016 | B15: 231 | C15: 142 | D15: 0.61471861 | E15: 0.53246753 | F15: 0.76056338 | G15: 0.85546971 | H15: 0.021645022 | I15: 0.03030303 | J15: 5 | K15: 7 | L15: 5 | M15: 0.5021645 | N15: 116 | O15: 231 | P15: 10 | Q15: 23.1 | R15: 4.5 | S15: 45 | T15: 0 | U15: 0
A16: COBEN_CZCOBEN017 | B16: 183 | C16: 129 | D16: 0.70491803 | E16: 0.43715847 | F16: 0.79844961 | G16: 0.87858008 | H16: 0.021857923 | I16: 0.016393443 | J16: 4 | K16: 3 | L16: 2 | M16: 0.54098361 | N16: 99 | O16: 183 | P16: 10 | Q16: 18.3 | R16: 2 | S16: 20 | T16: 0 | U16: 0
A17: COBEN_CZCOBEN018 | B17: 255 | C17: 153 | D17: 0.6 | E17: 0.58039216 | F17: 0.69934641 | G17: 0.87449672 | H17: 0.043137255 | I17: 0.039215686 | J17: 11 | K17: 10 | L17: 3 | M17: 0.49019608 | N17: 125 | O17: 255 | P17: 9 | Q17: 28.333333 | R17: 4 | S17: 36 | T17: 1 | U17: 0.58150769
A18: COBEN_CZCOBEN019 | B18: 125 | C18: 93 | D18: 0.744 | E18: 0.392 | F18: 0.8172043 | G18: 0.87241525 | H18: 0.024 | I18: 0.008 | J18: 3 | K18: 1 | L18: 3 | M18: 0.52 | N18: 65 | O18: 125 | P18: 11 | Q18: 11.363636 | R18: 1.3636364 | S18: 15 | T18: 0 | U18: 0
A19: COBEN_CZCOBEN021 | B19: 156 | C19: 110 | D19: 0.70512821 | E19: 0.42948718 | F19: 0.80909091 | G19: 0.86524044 | H19: 0.0064102564 | I19: 0 | J19: 1 | K19: 0 | L19: 4 | M19: 0.5375 | N19: 86 | O19: 160 | P19: 7 | Q19: 22.285714 | R19: 2.4285714 | S19: 17 | T19: 0 | U19: 0
A20: COBEN_CZCOBEN022 | B20: 162 | C20: 121 | D20: 0.74691358 | E20: 0.37037037 | F20: 0.84297521 | G20: 0.88789716 | H20: 0.012345679 | I20: 0 | J20: 2 | K20: 0 | L20: 3 | M20: 0.54268293 | N20: 89 | O20: 164 | P20: 14 | Q20: 11.571429 | R20: 1.6428571 | S20: 23 | T20: 0 | U20: 0
A21: COBEN_CZCOBEN023 | B21: 154 | C21: 119 | D21: 0.77272727 | E21: 0.35064935 | F21: 0.84033613 | G21: 0.90846274 | H21: 0.025974026 | I21: 0.0064935065 | J21: 4 | K21: 1 | L21: 3 | M21: 0.56774194 | N21: 88 | O21: 155 | P21: 14 | Q21: 11 | R21: 1.4285714 | S21: 20 | T21: 0 | U21: 0
A22: COBEN_CZCOBEN024 | B22: 154 | C22: 96 | D22: 0.62337662 | E22: 0.55844156 | F22: 0.70833333 | G22: 0.83723932 | H22: 0.025974026 | I22: 0.012987013 | J22: 4 | K22: 2 | L22: 2 | M22: 0.52597403 | N22: 81 | O22: 154 | P22: 11 | Q22: 14 | R22: 1.3636364 | S22: 15 | T22: 0 | U22: 0
A23: COBEN_CZCOBEN025 | B23: 192 | C23: 126 | D23: 0.65625 | E23: 0.484375 | F23: 0.78571429 | G23: 0.85724951 | H23: 0.041666667 | I23: 0.015625 | J23: 8 | K23: 3 | L23: 3 | M23: 0.50777202 | N23: 98 | O23: 193 | P23: 13 | Q23: 14.769231 | R23: 2.6153846 | S23: 34 | T23: 0 | U23: 0
A24: COBEN_CZCOBEN026 | B24: 95 | C24: 72 | D24: 0.75789474 | E24: 0.41052632 | F24: 0.77777778 | G24: 0.86953034 | H24: 0 | I24: 0 | J24: 0 | K24: 0 | L24: 3 | M24: 0.63157895 | N24: 60 | O24: 95 | P24: 14 | Q24: 6.7857143 | R24: 0.78571429 | S24: 11 | T24: 0 | U24: 0
A25: COBEN_CZCOBEN027 | B25: 109 | C25: 89 | D25: 0.81651376 | E25: 0.28440367 | F25: 0.87640449 | G25: 0.90664194 | H25: 0.027522936 | I25: 0 | J25: 3 | K25: 0 | L25: 2 | M25: 0.54054054 | N25: 60 | O25: 111 | P25: 3 | Q25: 36.333333 | R25: 4.6666667 | S25: 14 | T25: 0 | U25: 0
A26: COBEN_CZCOBEN029 | B26: 182 | C26: 132 | D26: 0.72527473 | E26: 0.4010989 | F26: 0.82575758 | G26: 0.89501044 | H26: 0.021978022 | I26: 0.021978022 | J26: 4 | K26: 4 | L26: 2 | M26: 0.54644809 | N26: 100 | O26: 183 | P26: 16 | Q26: 11.375 | R26: 1.6875 | S26: 27 | T26: 0 | U26: 0
A27: COBEN_CZCOBEN030 | B27: 129 | C27: 99 | D27: 0.76744186 | E27: 0.36434109 | F27: 0.82828283 | G27: 0.89796253 | H27: 0.023255814 | I27: 0 | J27: 3 | K27: 0 | L27: 3 | M27: 0.6 | N27: 75 | O27: 125 | P27: 14 | Q27: 9.2142857 | R27: 0.71428571 | S27: 10 | T27: 0 | U27: 0
A28: COBEN_CZCOBEN032 | B28: 166 | C28: 118 | D28: 0.71084337 | E28: 0.43975904 | F28: 0.78813559 | G28: 0.88357331 | H28: 0.012048193 | I28: 0.018072289 | J28: 2 | K28: 3 | L28: 4 | M28: 0.5748503 | N28: 96 | O28: 167 | P28: 9 | Q28: 18.444444 | R28: 2.5555556 | S28: 23 | T28: 0 | U28: 0
A29: COBEN_CZCOBEN033 | B29: 178 | C29: 108 | D29: 0.60674157 | E29: 0.53932584 | F29: 0.75925926 | G29: 0.81118595 | H29: 0.011235955 | I29: 0.011235955 | J29: 2 | K29: 2 | L29: 3 | M29: 0.53932584 | N29: 96 | O29: 178 | P29: 8 | Q29: 22.25 | R29: 2.375 | S29: 19 | T29: 0 | U29: 0
A30: COBEN_CZCOBEN034 | B30: 103 | C30: 83 | D30: 0.80582524 | E30: 0.2815534 | F30: 0.89156627 | G30: 0.87920447 | H30: 0 | I30: 0.0097087379 | J30: 0 | K30: 1 | L30: 3 | M30: 0.6039604 | N30: 61 | O30: 101 | P30: 1 | Q30: 103 | R30: 12 | S30: 12 | T30: 0 | U30: 0
A31: COBEN_CZCOBEN035 | B31: 110 | C31: 80 | D31: 0.72727273 | E31: 0.41818182 | F31: 0.8 | G31: 0.8547971 | H31: 0 | I31: 0.0090909091 | J31: 0 | K31: 1 | L31: 3 | M31: 0.59090909 | N31: 65 | O31: 110 | P31: 4 | Q31: 27.5 | R31: 3 | S31: 12 | T31: 0 | U31: 0
A32: COBEN_CZCOBEN036 | B32: 148 | C32: 100 | D32: 0.67567568 | E32: 0.50675676 | F32: 0.73 | G32: 0.86442245 | H32: 0 | I32: 0.02027027 | J32: 0 | K32: 3 | L32: 3 | M32: 0.50657895 | N32: 77 | O32: 152 | P32: 10 | Q32: 14.8 | R32: 2.9 | S32: 29 | T32: 0 | U32: 0
A33: COBEN_CZCOBEN038 | B33: 87 | C33: 70 | D33: 0.8045977 | E33: 0.31034483 | F33: 0.85714286 | G33: 0.8784793 | H33: 0.011494253 | I33: 0 | J33: 1 | K33: 0 | L33: 1 | M33: 0.62068966 | N33: 54 | O33: 87 | P33: 9 | Q33: 9.6666667 | R33: 1 | S33: 9 | T33: 0 | U33: 0
A34: COBEN_CZCOBEN039 | B34: 114 | C34: 89 | D34: 0.78070175 | E34: 0.33333333 | F34: 0.85393258 | G34: 0.88545059 | H34: 0.035087719 | I34: 0 | J34: 4 | K34: 0 | L34: 1 | M34: 0.51754386 | N34: 59 | O34: 114 | P34: 5 | Q34: 22.8 | R34: 3 | S34: 15 | T34: 0 | U34: 0
A35: COBEN_CZCOBEN040 | B35: =Median!B$3 -> 157.5 | C35: =Median!C$3 -> 110 | D35: =Median!D$3 -> 0.69680851 | E35: =Median!E$3 -> 0.44512195 | F35: =Median!F$3 -> 0.79347826 | G35: =Median!G$3 -> 0.86064224 | H35: =Median!H$3 -> 0.013513514 | I35: =Median!I$3 -> 0.014084507 | ... U35: =Median!U$3 -> 0
A36: COBEN_CZCOBEN042 | B36: 124 | C36: 104 | D36: 0.83870968 | E36: 0.26612903 | F36: 0.875 | G36: 0.92794453 | H36: 0.016129032 | I36: 0.032258065 | J36: 2 | K36: 4 | L36: 3 | M36: 0.56 | N36: 70 | O36: 125 | P36: 13 | Q36: 9.5384615 | R36: 1.1538462 | S36: 15 | T36: 0 | U36: 0
A37: COBEN_CZCOBEN044 | B37: 113 | C37: 83 | D37: 0.73451327 | E37: 0.4159292 | F37: 0.79518072 | G37: 0.86275986 | H37: 0 | I37: 0 | J37: 0 | K37: 0 | L37: 3 | M37: 0.59292035 | N37: 67 | O37: 113 | P37: 12 | Q37: 9.4166667 | R37: 1 | S37: 12 | T37: 0 | U37: 0
A38: COBEN_CZCOBEN046 | B38: 205 | C38: 136 | D38: 0.66341463 | E38: 0.50731707 | F38: 0.74264706 | G38: 0.87316889 | H38: 0.029268293 | I38: 0.019512195 | J38: 6 | K38: 4 | L38: 3 | M38: 0.53658537 | N38: 110 | O38: 205 | P38: 18 | Q38: 11.388889 | R38: 1.6111111 | S38: 29 | T38: 1 | U38: 0.61668757
A39: COBEN_CZCOBEN047 | B39: 173 | C39: 117 | D39: 0.67630058 | E39: 0.45086705 | F39: 0.81196581 | G39: 0.84636687 | H39: 0.040462428 | I39: 0.011560694 | J39: 7 | K39: 2 | L39: 3 | M39: 0.5433526 | N39: 94 | O39: 173 | P39: 14 | Q39: 12.357143 | R39: 1.3571429 | S39: 19 | T39: 0 | U39: 0
A40: COBEN_CZCOBEN048 | B40: 129 | C40: 98 | D40: 0.75968992 | E40: 0.36434109 | F40: 0.83673469 | G40: 0.88479566 | H40: 0.03875969 | I40: 0 | J40: 5 | K40: 0 | L40: 4 | M40: 0.51937984 | N40: 67 | O40: 129 | P40: 7 | Q40: 18.428571 | R40: 2.4285714 | S40: 17 | T40: 0 | U40: 0
...

Sheet Median
B1: Lex_total_tokens | C1: Lex_unique_types | D1: Lex_TTR | E1: Lex_repetition_ratio | F1: Lex_hapax_ratio | G1: Lex_HDD | H1: Sem_personal_ratio | I1: Sem_vague_ratio | J1: Sem_personal_count | K1: Sem_vague_count | L1: Sem_semantic_category_count | M1: Sem_content_density | N1: Sem_n_content | O1: Sem_n_tokens | P1: Syn_num_sent | Q1: Syn_MLU | R1: Syn_sub_per_sent | S1: Syn_total_sub | T1: Syn_hes | U1: Syn_hes_per_min
A2: formula | B2: =MEDIAN(Linguistic_parameters2__2[Lex_total_tokens]) -> 157.5 | C2: =MEDIAN(Linguistic_parameters2__2[Lex_unique_types]) -> 110 | D2: =MEDIAN(Linguistic_parameters2__2[Lex_TTR]) -> 0.69680851 | E2: =MEDIAN(Linguistic_parameters2__2[Lex_repetition_ratio]) -> 0.44512195 | F2: =MEDIAN(Linguistic_parameters2__2[Lex_hapax_ratio]) -> 0.79347826 | G2: =MEDIAN(Linguistic_parameters2__2[Lex_HDD]) -> 0.86064224 | H2: =MEDIAN(Linguistic_parameters2__2[Sem_personal_ratio]) -> 0.013513514 | I2: =MEDIAN(Linguistic_parameters2__2[Sem_vague_ratio]) -> 0.014084507 | J2: =MEDIAN(Linguistic_parameters2__2[Sem_personal_count]) -> 2 | K2: =MEDIAN(Linguistic_parameters2__2[Sem_vague_count]) -> 2 | L2: =MEDIAN(Linguistic_parameters2__2[Sem_semantic_category_count]) -> 3 | M2: =MEDIAN(Linguistic_parameters2__2[Sem_content_density]) -> 0.54938272 | N2: =MEDIAN(Linguistic_parameters2__2[Sem_n_content]) -> 88 | O2: =MEDIAN(Linguistic_parameters2__2[Sem_n_tokens]) -> 158.5 | P2: =MEDIAN(Linguistic_parameters2__2[Syn_num_sent]) -> 10 | Q2: =MEDIAN(Linguistic_parameters2__2[Syn_MLU]) -> 15.816667 | R2: =MEDIAN(Linguistic_parameters2__2[Syn_sub_per_sent]) -> 2.1428571 | S2: =MEDIAN(Linguistic_parameters2__2[Syn_total_sub]) -> 20 | T2: =MEDIAN(Linguistic_parameters2__2[Syn_hes]) -> 0 | U2: =MEDIAN(Linguistic_parameters2__2[Syn_hes_per_min]) -> 0
B3: 157.5 | C3: 110 | D3: 0.69680851 | E3: 0.44512195 | F3: 0.79347826 | G3: 0.86064224 | H3: 0.013513514 | I3: 0.014084507 | J3: 2 | K3: 2 | L3: 3 | M3: 0.54938272 | N3: 88 | O3: 158.5 | P3: 10 | Q3: 15.816667 | R3: 2.1428571 | S3: 20 | T3: 0 | U3: 0

Sheet Transcript
A1: Transcript
A2: Proste jsme věli do Brna a v Brně dnes jsem se podrobil vyšetření, doufám, že to dopadne jakž takš, že ještě budu schopen samostatného života. Manželka na mě čeká na chodbě i se synem, který mě jsem doprovodil. Ještě můžu si povídat, takže co budu říkat, že v Brně mám vnůčku, snachu, rácem za ní majezdíme i s manželkou. Króvnitokov v Olomouci mám syna, dvěma malýma dětma. Tam taky rádi jezdíme, zajména za Kacenkou a Ondráškem, který jsou fajn báětční dětičky 2 a 5 let. Rádi si s ním a hrajem. Až tohle zkončí, zajedem zpátky Ksinovy, tam se naobědváme a vyrazíme domů do českých budělovic. Vlastně ne, to jenom k českým budělovicím do Hosíná, což je malá obec nad českými budělovicami.
A3: Napajci stani se tramvajových a trolleybusových trati. Napajci stani se tramvajových a trolleybusových trati slouží k napájení napajci v úseku uvedené trakce. Obvykle jsou napájeni z nadřezené distribuční sítě, 22 kV. Obsahuji trakční transformátor, kdy se na 5,2 200 V transformuje na trakční na 5,25 V střídavých a poté dedou směrňovací skupin 600 V dc. Stejnostměrné napěti se vývádi do jednotlivých vývodových polízí stící mi rychlove pínačí a přivádi se k trolleyom vedení pro tramvajové a trolleybusové trate. U tramvajových trati je trollojové vedení vedené v osé kolejí s tím, že je polarizace v trolleyi plus, zatím co v koleji ve spětném kolejnícovém vedení je polarizace minus. U trolleybusových trati máme oba polina hoře, máme tam jak kladný tak záporný pohl, to znamená, máme tam 600 V plus minus a vzdálenost mezi trolleymi trolleybusových trati je 60 cm, 60 mm, to je standardní vzdálenost, která je dana normou, dodržuje se samozřejmě i na přímých tratích i v oblouku. U tramvajových trati je istou specifikaci dopraveněho podníku města Brnaže polarizace v kolejí je plusová a v trolleyi minusová. Je to vlastně dáno tím, že rozdíl potenciál s měrem odzemě od koleje k trolleyí je minus 600 V. Je to v podstatě dáno historicky někdy z roku 19, kdy se začel dělá výrávě nebo kdy se začelá tvořit elektrifikovaná síť a ovlivnila to především chemické služení půdy.
A4: Ménuju se Vladka Šabacka a narodila jsem se rodičům v Praze. Bydleli jsme v pohraničí, v přírode, v takovém domku. Mám sestru starší, mamiňka mě dala brzo do jeslí, sestra mě tam musela doprovázet a hlídat, než přišla pani učitelka. A tak to bylo náročné asi pro celou rodinu, protože mamiňka chtěla chodit do Praze. A si když mě bylo 5 let, jsme se odstěhovali s rodinou do Brna. A to bylo v roce 1961. Sme se nastěhovali do rodiného domku a já jsem se do toho domku nyní dokonce vrátila po letech. Chodila jsem do školy na Stanikovu, škola mě moc nebavila, protože jsem jí líbila jednou pani učitelka v 1.3. A potom ve 3. jinak ti učitele se moc hezky tak nechovali, takže to byl asi důvod a taky mě učení moc nebavilo, moc se mě ani nedářil. Ale dářil se mě těl od svik. Po základní škole jsem šla studovat na ekonomickou školu, kde jsem po 4 letech zdárně odmaturovala a chvíli jsem pracovala v uřednických zaměstnáních.
A5: Vpáteck odpaledné jezdký má na našich harupů, jezdkým tam vlakém asi hodinu. Když přijedu na náhná chéří, tak musí mít po silnici 3 km ty pěšky. Všetní den zice jezdí jednou deně autobus, ale ten mi většenou ujede. A mě to nevadí, tože je léto, zvědí suníčko, silnica vademe ze poli. Vdáli většení z kotačníjí zajíci. A když dají na harupku, tak začnout tím, že si udělám kaffe. A potom se jdu podívat ven, co mi tam květa, jaké tam jí tady motíly. Včerám se snažím vyhybat, tože když na ně stoupnu, tak to mi votečeno hádostoborí. Tak tam mám třeba dvě budleje, těm se sříká motílíkéř. A po nich skutečně jsou motílci jako děví. Slítej se tam na velký houfech, zvitáno fotiák a hrozně mě baví si je fotit. Ze předů, ze zadů, oni potvrhydyž tam sedí a sosejí, tak mají křidílka u sebe. Takže musím čekat, až si s nima zamávají, takže ta fotka by byla taková nijaká, že křidílka u sebe a to je jejich ošklivá hlavička, to není od co stá.
A6: Tak bude to příběh z Brna, pro vělo to v roce 1969 v Srpnu, bylo v Brně mistrosvý sět a v cyklistice. A nějaký kamarác se jsem chystal, protože otec byl jaký funkcionár, tak mě řekl, že s ním můžu jít. Tak jsme věli do Brna, myslím, že to byla asi 19 týho. A jeden den jsme byli na to mistrosvý sět a druhý den bylo 21 týho, takže oni odjeli s ocem. Mimo Brno já jsem šal do ulic a tady se demonstroval, takže jsem se toho samozřejmě zúčastnil demonstracie a samozřejmě jsem se nechal chytit. Takže mě chytili v ulicích, já jsem měl špinavý ruce, protože jsem stavil barikády, tak mě hned zavřeli s tím, že jsem poniházal kamení a že jsem na někřičel, že jsou gestapáci, takže jsem tady kousek odsud, potom seděl ve vazbě štery měsíce a za toto napadení těch veřejně čenitelů jsem dostal nejdří v pův roku a potom rok zbytek jsem odseděl v ostravě veřmánicích a tady na to Brno mám díky tomu poměrně špatní spomínky, protože to bylo takový, že jsem ty štery měsíce viděl z okna, jenom tady tu nemocnici právě a jinak teda to bylo samozřejmě, stracená doby a protože to bylo těsně potom, co mě bylo 18 a měl jsem představit, že budu něco v životě ještě schopenu dělat a nějak se mi to vtu chvíli, se mi to...
A7: Ménuji se Miroslava Hruškova, bydlý v Brně, nási dliští ve starajem Liskovci. Jsem daná, můj manžel semenuje Libor Hruška, mám jednoho siná, který semenuje Petr Hofman, toho mám z prvního manželství, je mu 39 let, je ženatý a bydlý v Kouřimi. Tady u Brna má dvě děti, takže tím pádem já mám dva vnuky. Jeden semenuje Pavlík, narodil se v roce 2010, a druhý semenuje Tomáš a narodil se 19. letna 2017. Syn udělal hotelovou školu, ale bohužel, ho to špatně živilo, takže v momentě, kdy se oženil, tak změnil zaměstnání a dělá řidiče u dopravního podníku Města Brna. Teď to vypadá, že si polipší, protože máma turitu, tak bude může zaučíje na výpravčího, vyvodovně v medlánkách. Já jsem většinu života pracovala jako učetní, v posedních 20 letech jsem dělala vědouci ekonomického oddělení na fakultě architektury vysokého učení technického v Brně. Pracovala jsem i přes duchod, iště dva roky po duchodě, a pak jsem dál spolupracovala s fakultou na projekty, které měli od Europské unie jako finanční manažér. Teď v světě vlastně si užívám duchodu, mám chalupu, kdy je zahárdničím, ale neustále mě bývali kolegové oslovují, takže momentálně chodím na výpomoc na fakultu informací technologii vysokého učení.
A8: Minulý týden jsem byla na dovolené. Byla jsem s cestovkou, s kamarádkami. Jeli jsme do Francie. Bylo to bezvatný zájezd. Byli jsme v Alsasku a v Oghézách. Byla to taková cesta v kraji Výna. Bylo to úžasné. Hodně jsme toho viděli, nebyli tam noční přejezdy. Spali jsme v nějaké takové obyčejné premiér. Klasno problém bylo, že jsme se večerné měli kde scházet. Takže jsme si to výmkomuseli dávit v kufru autobusu. S řidi Čemano, ale to teda vůbec nevadilo. Bylo to úžasné. Svitil s luníčko. Měli jsme krásný počasí a ty městečka, který my jsme proěli a procházeli. Byli nádherný. Hodně jsem fotila, aby s toho moje děti taky něco měli. Říkali, že mám hodně fotit, ale já nerajda fotím. Jenom, že tento krát jsem se teda překonala, když už to musela být. Tak jsem udělala spoustu fotek, jednomře z polovina z toho stejně nebyla na nic. Naštěstí se měla sebou dobré kamarádky, takže oni mi potom doplnili moc fotek, které jsem potom dala. Na internet je ten poslala. Takže to bylo skvělí a měli jsme dobrou partu. A dobrého průvodce. Už jsem se přihlásila na další zájezd 3-4 rohnec, která je prázdný. Tak si myslím, že to pěkně výjde.
A9: Když jsem študoval, tak tady na Slovensku nebyla žádna ekonomie, takže všichni studovali v Praze. Tout dobou s námi také chodili madži a s nimi to bavili vždy strášné alegrace. Pomatuju se, že jeden z nich menoval se Maurer Zoltán, chodil s děvčenou, která bá zkošit. Zoltán byl takový jako spíš jarmará z hlavou na hoře. Marienka, která byla ta jeho snoubenka nebo jeho psí, tak když ten krásetl tak neříkal osice. Tam byla asi také jako maliček Marienka a oni dělali mimika. Děvče zavidleli na kolei, kde byly na pateráku. A tam pochopitelně to bylo takový, že neutulný, takže pořád si vymejřeli, jak by to kde předělali a představili, aby to tam měli trošku kemitlych. Vždycky se přestavouval nějak z tent nábyt, jak rok posunula, už to bylo něco úplně jiného. Když tam přišel zanimlala naště o Zoltán, tak Marienka říkala, Zoli byl by si také láskavý a pomohol nám tu náprestěhou je tuto palandu. Vždycky se postavil a povidáli, mimika moja, ujasníme si pojmi, čo je toto palanda. No a potom teda i přestavila už to bylo naderné.
A10: Sista jsem mě docela trochu překvapila, myslá jsem si, že to bude pohodlnější, že byla jsem tam strašně na mačkaná, nemohla jsem se ani pohnovat. To teda jsem přiklela, že bude lepší. A teď potom až tady skončím v kampusu, tak poru za hankou. Už jsme se neviděli tolik lat, tak jsem zjeda váž, jak vypadá, co má za novenky. A pak až se vrátim, tak už bych snad měla mít teda zapřeře zbravení auto, a mohli by jsme ještě pro kalvá doskonečně, aby jsme to tam vyzvedli. Už se na nás budou i zlobyt, asi, že to dlouho trvá. Růbám, že Rubík bude moc ještě se mnou, protože, jestli bude špatný počasí, tak bych nereda, že může by jít ledovka, a bych to ještě někde, ale nevím, ne napohřejal, a takže radši by jel se mnou. No, pak udláme asi to výběrovko, teda na ty dveře, protože už v to je tristní, jak je to vypadá v tom baráku, takže to konečně s na tam vybereme. No a jsem ráda, že už jsme s holkami napekl, že to máme připravené, a těším se na rozálku, že s ním podutí na někam, až je předvánoci se podívat, třeba, ale nevím, podeme do divatla nebo na něco, aby jsme si to uželi trošku to vánoční, to vana být nějaký volno bude, a s nád i Martina se připojí, takže bude to fajn, když podeme spolu. Pavel se už uzdravuje, tak už bude lepší taky, a těším se, že podeme si Janou Hradeckou, teda na nějakou tu její procházku, kterou plánují asi dva měsíce, takže se vydáme a uděláme turistiku, takových 10-15 km pojedeme.
A11: V sejtěku absolvujem zaujímavé vyšetreně neuropsychologické tomografie a děláče je to na dva dny. V srdce výsledky budou a zledem k tomu kolik mám léd a předpokladám, že ještě nejakých pár desítek let budu žít, budu mít možnost podívat. V srdce budou se podívat, jak se mlel na tom slediska dušemní schopnosti. V srdce budou se podívat, jaké to bude v 70-80. Kdybych měl takový gen, jak má otec, který oslávil 94 let před minulý týden, tak bych to měl na papíře a dokázal bych se podle toho jako řídit. Otec se neustále stěžuje, že ho bolí nohy, brzího, klouby a tak dále. Tato rozhduvící je to, že máte takzvané čistou hlavu, to znamenál netrpí ten nejakým Parkinsonem, Alzheimerem, demenci a další chorobami. To ostatné je dané věkem, který tělo se větší.
A12: V dnešní vánoce, nebo letošný, to už vlastně jsou londské vánoce, se moc nepovedli, protože nebyl žádný sních, vnočky byli sklamane, stihli udělá dělá dělá dělá sněhuláka. Pak jsme chtěli dna procházku pravidelnou na Silvestra do lesa, kde se schází spousta lidí i tisíce, tam si pěkně blahopřejí to nového rok. U zdraví se je to moc příjemné, ale letos, protože byla obleva, tak přišlo mnoho méně lidí, hodně lidí, když viděli to počas, si zůstali doma, ale přesto ti skálni tam přišli a šlapali jsme v blate, žádný les nebyl krásný bílej, ale já jsem to vydržala, ani jsem nespadla, kluzalo se to strašně. Dokonce vnočky ani nechtěli s nám jít, tak zostali doma a my staři jsme se tam vypravili. No, potom už to bylo jednoduchý, zase o půlnoci nikdo nebyl venku, si cese jsou se nějakým ten malý ochronstřoj udělal, ale na ulici nebylo ani živáčka, všichni byli zalezli. No, nový rok to jsme se rozhodli, že když jsme sami s dědou, že si uděláme pižamu ve nový rok, aby byla nějaká změna, voletne jsme si pustili koncert zvídně, pak jsme si dali pozdější obět a nový rok byl za námi.
... A415: Měli předatele, nakázíme se v brně, jsou čas zrobili jsou na nějakém vysětriní, které je pro jiné odborníky a vykterim se nikdy nevizlám. Někdy jsem nebyl takto vysětrinovaný, to velice zajímává metoda. A jinak přicházíme k lekkarským vysětriním minimalně. Jedno je vzdravotným zaryzení, takže bych řekl, že jsem vzde, že jsem dopravil mým synem, který je dobrý řidičem. Cítil jsem se bezpečně přijíř, že jeho auto je taktež bezpečné, pekne a více mě líbí. Vypelnívá jeden svého důchodu, tím že jsem tady na tomto zářízení, které je pro mě velice zajímavé. Narodil se se 12.6.46 v přerově, přerově krásném.

Sheet wrong_style
A1: Subject.1 | B1: Subject.2 | C1: Subject.3 | D1: Subject.4 | E1: Subject.5 | F1: Subject.6 | G1: Subject.7 | H1: Subject.8 | I1: Subject.9 | J1: Subject.10 | K1: Subject.11 | L1: Subject.12 | M1: Subject.13 | N1: Subject.14 | O1: Subject.15 | P1: Subject.16 | Q1: Subject.17 | R1: Subject.18 | S1: Subject.19 | T1: Subject.20 | U1: Subject.21 | V1: Subject.22 | W1: Lex_total_tokens | X1: Lex_unique_types | Y1: Lex_TTR | Z1: Lex_repetition_ratio | AA1: Lex_hapax_ratio | AB1: Lex_HDD | AC1: Sem_personal_ratio | AD1: Sem_vague_ratio | AE1: Sem_personal_count | AF1: Sem_vague_count | AG1: Sem_semantic_category_count | AH1: Sem_content_density | AI1: Sem_n_content | AJ1: Sem_n_tokens | AK1: Syn_num_sent | AL1: Syn_MLU | AM1: Syn_sub_per_sent | AN1: Syn_total_sub | AO1: Syn_hes | AP1: Syn_hes_per_min | AQ1: Transcript
A2: COBEN_CZCOBEN000 | B2: 122 | C2: 95 | D2: 0.7786885245901639 | E2: 0.38524590163934425 | F2: 0.7894736842105263 | G2: 0.9087779950192721 | H2: 0.01639344262295082 | I2: 0.01639344262295082 | J2: 2 | K2: 2 | L2: 4 | M2: 0.5491803278688525 | N2: 67 | O2: 122 | P2: 8 | Q2: 15.25 | R2: 1.875 | S2: 15 | T2: 0 | U2: 0.0 | V2: Proste jsme věli do Brna a v Brně dnes jsem se podrobil vyšetření, doufám, že to dopadne jakž takš, že ještě budu schopen samostatného života. Manželka na mě čeká na chodbě i se synem, který mě jsem doprovodil. Ještě můžu si povídat, takže co budu říkat, že v Brně mám vnůčku, snachu, rácem za ní majezdíme i s manželkou. Króvnitokov v Olomouci mám syna, dvěma malýma dětma. Tam taky rádi jezdíme, zajména za Kacenkou a Ondráškem, který jsou fajn báětční dětičky 2 a 5 let. Rádi si s ním a hrajem. Až tohle zkončí, zajedem zpátky Ksinovy, tam se naobědváme a vyrazíme domů do českých budělovic. Vlastně ne, to jenom k českým budělovicím do Hosíná, což je malá obec nad českými budělovicami.
A3: COBEN_CZCOBEN002 | B3: 227 | C3: 140 | D3: 0.6167400881057269 | E3: 0.5286343612334802 | F3: 0.7642857142857142 | G3: 0.8448915039645281 | H3: 0.004405286343612335 | I3: 0.004405286343612335 | J3: 1 | K3: 1 | L3: 2 | M3: 0.6167400881057269 | N3: 140 | O3: 227 | P3: 10 | Q3: 22.7 | R3: 2.1 | S3: 21 | T3: 0 | U3: 0.0 | V3: Napajci stani se tramvajových a trolleybusových trati. Napajci stani se tramvajových a trolleybusových trati slouží k napájení napajci v úseku uvedené trakce. Obvykle jsou napájeni z nadřezené distribuční sítě, 22 kV. Obsahuji trakční transformátor, kdy se na 5,2 200 V transformuje na trakční na 5,25 V střídavých a poté dedou směrňovací skupin 600 V dc. Stejnostměrné napěti se vývádi do jednotlivých vývodových polízí stící mi rychlove pínačí a přivádi se k trolleyom vedení pro tramvajové a trolleybusové trate. U tramvajových trati je trollojové vedení vedené v osé kolejí s tím, že je polarizace v trolleyi plus, zatím co v koleji ve spětném kolejnícovém vedení je polarizace minus. U trolleybusových trati máme oba polina hoře, máme tam jak kladný tak záporný pohl, to znamená, máme tam 600 V plus minus a vzdálenost mezi trolleymi trolleybusových trati je 60 cm, 60 mm, to je standardní vzdálenost, která je dana normou, dodržuje se samozřejmě i na přímých tratích i v oblouku. U tramvajových trati je istou specifikaci dopraveněho podníku města Brnaže polarizace v kolejí je plusová a v trolleyi minusová. Je to vlastně dáno tím, že rozdíl potenciál s měrem odzemě od koleje k trolleyí je minus 600 V. Je to v podstatě dáno historicky někdy z roku 19, kdy se začel dělá výrávě nebo kdy se začelá tvořit elektrifikovaná síť a ovlivnila to především chemické služení půdy.
A4: COBEN_CZCOBEN004 | B4: 171 | C4: 111 | D4: 0.6491228070175439 | E4: 0.47953216374269003 | F4: 0.8018018018018018 | G4: 0.8293285937725278 | H4: 0.04678362573099415 | I4: 0.0 | J4: 8 | K4: 0 | L4: 4 | M4: 0.5176470588235295 | N4: 88 | O4: 170 | P4: 13 | Q4: 13.153846153846153 | R4: 1.5384615384615385 | S4: 20 | T4: 0 | U4: 0.0 | V4: Ménuju se Vladka Šabacka a narodila jsem se rodičům v Praze. Bydleli jsme v pohraničí, v přírode, v takovém domku. Mám sestru starší, mamiňka mě dala brzo do jeslí, sestra mě tam musela doprovázet a hlídat, než přišla pani učitelka. A tak to bylo náročné asi pro celou rodinu, protože mamiňka chtěla chodit do Praze. A si když mě bylo 5 let, jsme se odstěhovali s rodinou do Brna. A to bylo v roce 1961. Sme se nastěhovali do rodiného domku a já jsem se do toho domku nyní dokonce vrátila po letech. Chodila jsem do školy na Stanikovu, škola mě moc nebavila, protože jsem jí líbila jednou pani učitelka v 1.3. A potom ve 3. jinak ti učitele se moc hezky tak nechovali, takže to byl asi důvod a taky mě učení moc nebavilo, moc se mě ani nedářil. Ale dářil se mě těl od svik. Po základní škole jsem šla studovat na ekonomickou školu, kde jsem po 4 letech zdárně odmaturovala a chvíli jsem pracovala v uřednických zaměstnáních.
A5: COBEN_CZCOBEN005 | B5: 175 | C5: 131 | D5: 0.7485714285714286 | E5: 0.3657142857142857 | F5: 0.8473282442748091 | G5: 0.8995728870825053 | H5: 0.02857142857142857 | I5: 0.011428571428571429 | J5: 5 | K5: 2 | L5: 4 | M5: 0.5574712643678161 | N5: 97 | O5: 174 | P5: 13 | Q5: 13.461538461538462 | R5: 1.9230769230769231 | S5: 25 | T5: 0 | U5: 0.0 | V5: Vpáteck odpaledné jezdký má na našich harupů, jezdkým tam vlakém asi hodinu. Když přijedu na náhná chéří, tak musí mít po silnici 3 km ty pěšky. Všetní den zice jezdí jednou deně autobus, ale ten mi většenou ujede. A mě to nevadí, tože je léto, zvědí suníčko, silnica vademe ze poli. Vdáli většení z kotačníjí zajíci. A když dají na harupku, tak začnout tím, že si udělám kaffe. A potom se jdu podívat ven, co mi tam květa, jaké tam jí tady motíly. Včerám se snažím vyhybat, tože když na ně stoupnu, tak to mi votečeno hádostoborí. Tak tam mám třeba dvě budleje, těm se sříká motílíkéř. A po nich skutečně jsou motílci jako děví. Slítej se tam na velký houfech, zvitáno fotiák a hrozně mě baví si je fotit. Ze předů, ze zadů, oni potvrhydyž tam sedí a sosejí, tak mají křidílka u sebe. Takže musím čekat, až si s nima zamávají, takže ta fotka by byla taková nijaká, že křidílka u sebe a to je jejich ošklivá hlavička, to není od co stá.
A6: COBEN_CZCOBEN007 | B6: 230 | C6: 136 | D6: 0.591304347826087 | E6: 0.5391304347826087 | F6: 0.7794117647058824 | G6: 0.8177617952029815 | H6: 0.034782608695652174 | I6: 0.017391304347826087 | J6: 8 | K6: 4 | L6: 4 | M6: 0.4608695652173913 | N6: 106 | O6: 230 | P6: 6 | Q6: 38.333333333333336 | R6: 6.0 | S6: 36 | T6: 1 | U6: 0.5975496728726765 | V6: Tak bude to příběh z Brna, pro vělo to v roce 1969 v Srpnu, bylo v Brně mistrosvý sět a v cyklistice. A nějaký kamarác se jsem chystal, protože otec byl jaký funkcionár, tak mě řekl, že s ním můžu jít. Tak jsme věli do Brna, myslím, že to byla asi 19 týho. A jeden den jsme byli na to mistrosvý sět a druhý den bylo 21 týho, takže oni odjeli s ocem. Mimo Brno já jsem šal do ulic a tady se demonstroval, takže jsem se toho samozřejmě zúčastnil demonstracie a samozřejmě jsem se nechal chytit. Takže mě chytili v ulicích, já jsem měl špinavý ruce, protože jsem stavil barikády, tak mě hned zavřeli s tím, že jsem poniházal kamení a že jsem na někřičel, že jsou gestapáci, takže jsem tady kousek odsud, potom seděl ve vazbě štery měsíce a za toto napadení těch veřejně čenitelů jsem dostal nejdří v pův roku a potom rok zbytek jsem odseděl v ostravě veřmánicích a tady na to Brno mám díky tomu poměrně špatní spomínky, protože to bylo takový, že jsem ty štery měsíce viděl z okna, jenom tady tu nemocnici právě a jinak teda to bylo samozřejmě, stracená doby a protože to bylo těsně potom, co mě bylo 18 a měl jsem představit, že budu něco v životě ještě schopenu dělat a nějak se mi to vtu chvíli, se mi to...
A7: COBEN_CZCOBEN008 | B7: 197 | C7: 148 | D7: 0.751269035532995 | E7: 0.38071065989847713 | F7: 0.8243243243243243 | G7: 0.9132699894442647 | H7: 0.015228426395939087 | I7: 0.015228426395939087 | J7: 3 | K7: 3 | L7: 4 | M7: 0.6192893401015228 | N7: 122 | O7: 197 | P7: 10 | Q7: 19.7 | R7: 2.2 | S7: 22 | T7: 0 | U7: 0.0 | V7: Ménuji se Miroslava Hruškova, bydlý v Brně, nási dliští ve starajem Liskovci. Jsem daná, můj manžel semenuje Libor Hruška, mám jednoho siná, který semenuje Petr Hofman, toho mám z prvního manželství, je mu 39 let, je ženatý a bydlý v Kouřimi. Tady u Brna má dvě děti, takže tím pádem já mám dva vnuky. Jeden semenuje Pavlík, narodil se v roce 2010, a druhý semenuje Tomáš a narodil se 19. letna 2017. Syn udělal hotelovou školu, ale bohužel, ho to špatně živilo, takže v momentě, kdy se oženil, tak změnil zaměstnání a dělá řidiče u dopravního podníku Města Brna. Teď to vypadá, že si polipší, protože máma turitu, tak bude může zaučíje na výpravčího, vyvodovně v medlánkách. Já jsem většinu života pracovala jako učetní, v posedních 20 letech jsem dělala vědouci ekonomického oddělení na fakultě architektury vysokého učení technického v Brně. Pracovala jsem i přes duchod, iště dva roky po duchodě, a pak jsem dál spolupracovala s fakultou na projekty, které měli od Europské unie jako finanční manažér. Teď v světě vlastně si užívám duchodu, mám chalupu, kdy je zahárdničím, ale neustále mě bývali kolegové oslovují, takže momentálně chodím na výpomoc na fakultu informací technologii vysokého učení.
A8: COBEN_CZCOBEN009 | B8: 201 | C8: 131 | D8: 0.6517412935323383 | E8: 0.48258706467661694 | F8: 0.7938931297709924 | G8: 0.858675429649345 | H8: 0.014925373134328358 | I8: 0.024875621890547265 | J8: 3 | K8: 5 | L8: 3 | M8: 0.48258706467661694 | N8: 97 | O8: 201 | P8: 26 | Q8: 7.730769230769231 | R8: 0.7692307692307693 | S8: 20 | T8: 0 | U8: 0.0 | V8: Minulý týden jsem byla na dovolené. Byla jsem s cestovkou, s kamarádkami. Jeli jsme do Francie. Bylo to bezvatný zájezd. Byli jsme v Alsasku a v Oghézách. Byla to taková cesta v kraji Výna. Bylo to úžasné. Hodně jsme toho viděli, nebyli tam noční přejezdy. Spali jsme v nějaké takové obyčejné premiér. Klasno problém bylo, že jsme se večerné měli kde scházet. Takže jsme si to výmkomuseli dávit v kufru autobusu. S řidi Čemano, ale to teda vůbec nevadilo. Bylo to úžasné. Svitil s luníčko. Měli jsme krásný počasí a ty městečka, který my jsme proěli a procházeli. Byli nádherný. Hodně jsem fotila, aby s toho moje děti taky něco měli. Říkali, že mám hodně fotit, ale já nerajda fotím. Jenom, že tento krát jsem se teda překonala, když už to musela být. Tak jsem udělala spoustu fotek, jednomře z polovina z toho stejně nebyla na nic. Naštěstí se měla sebou dobré kamarádky, takže oni mi potom doplnili moc fotek, které jsem potom dala. Na internet je ten poslala. Takže to bylo skvělí a měli jsme dobrou partu. A dobrého průvodce. Už jsem se přihlásila na další zájezd 3-4 rohnec, která je prázdný. Tak si myslím, že to pěkně výjde.
A9: COBEN_CZCOBEN010 | B9: 180 | C9: 126 | D9: 0.7 | E9: 0.46111111111111114 | F9: 0.7698412698412699 | G9: 0.8935553268051348 | H9: 0.011111111111111112 | I9: 0.044444444444444446 | J9: 2 | K9: 8 | L9: 3 | M9: 0.5303867403314917 | N9: 96 | O9: 181 | P9: 12 | Q9: 15 | R9: 2.25 | S9: 27 | T9: 0 | U9: 0.0 | V9: Když jsem študoval, tak tady na Slovensku nebyla žádna ekonomie, takže všichni studovali v Praze. Tout dobou s námi také chodili madži a s nimi to bavili vždy strášné alegrace. Pomatuju se, že jeden z nich menoval se Maurer Zoltán, chodil s děvčenou, která bá zkošit. Zoltán byl takový jako spíš jarmará z hlavou na hoře. Marienka, která byla ta jeho snoubenka nebo jeho psí, tak když ten krásetl tak neříkal osice. Tam byla asi také jako maliček Marienka a oni dělali mimika. Děvče zavidleli na kolei, kde byly na pateráku. A tam pochopitelně to bylo takový, že neutulný, takže pořád si vymejřeli, jak by to kde předělali a představili, aby to tam měli trošku kemitlych. Vždycky se přestavouval nějak z tent nábyt, jak rok posunula, už to bylo něco úplně jiného. Když tam přišel zanimlala naště o Zoltán, tak Marienka říkala, Zoli byl by si také láskavý a pomohol nám tu náprestěhou je tuto palandu. Vždycky se postavil a povidáli, mimika moja, ujasníme si pojmi, čo je toto palanda. No a potom teda i přestavila už to bylo naderné.
A10: COBEN_CZCOBEN011 | B10: 273 | C10: 156 | D10: 0.5714285714285714 | E10: 0.5604395604395604 | F10: 0.7692307692307693 | G10: 0.8323827863368642 | H10: 0.014652014652014652 | I10: 0.02564102564102564 | J10: 4 | K10: 7 | L10: 4 | M10: 0.44727272727272727 | N10: 123 | O10: 275 | P10: 10 | Q10: 27.3 | R10: 4.8 | S10: 48 | T10: 0 | U10: 0.0 | V10: Sista jsem mě docela trochu překvapila, myslá jsem si, že to bude pohodlnější, že byla jsem tam strašně na mačkaná, nemohla jsem se ani pohnovat. To teda jsem přiklela, že bude lepší. A teď potom až tady skončím v kampusu, tak poru za hankou. Už jsme se neviděli tolik lat, tak jsem zjeda váž, jak vypadá, co má za novenky. A pak až se vrátim, tak už bych snad měla mít teda zapřeře zbravení auto, a mohli by jsme ještě pro kalvá doskonečně, aby jsme to tam vyzvedli. Už se na nás budou i zlobyt, asi, že to dlouho trvá. Růbám, že Rubík bude moc ještě se mnou, protože, jestli bude špatný počasí, tak bych nereda, že může by jít ledovka, a bych to ještě někde, ale nevím, ne napohřejal, a takže radši by jel se mnou. No, pak udláme asi to výběrovko, teda na ty dveře, protože už v to je tristní, jak je to vypadá v tom baráku, takže to konečně s na tam vybereme. No a jsem ráda, že už jsme s holkami napekl, že to máme připravené, a těším se na rozálku, že s ním podutí na někam, až je předvánoci se podívat, třeba, ale nevím, podeme do divatla nebo na něco, aby jsme si to uželi trošku to vánoční, to vana být nějaký volno bude, a s nád i Martina se připojí, takže bude to fajn, když podeme spolu. Pavel se už uzdravuje, tak už bude lepší taky, a těším se, že podeme si Janou Hradeckou, teda na nějakou tu její procházku, kterou plánují asi dva měsíce, takže se vydáme a uděláme turistiku, takových 10-15 km pojedeme.
A11: COBEN_CZCOBEN012 | B11: 133 | C11: 94 | D11: 0.706766917293233 | E11: 0.42857142857142855 | F11: 0.8085106382978723 | G11: 0.8554753437777981 | H11: 0.0 | I11: 0.015037593984962405 | J11: 0 | K11: 2 | L11: 2 | M11: 0.5373134328358209 | N11: 72 | O11: 134 | P11: 8 | Q11: 16.625 | R11: 2.0 | S11: 16 | T11: 0 | U11: 0.0 | V11: V sejtěku absolvujem zaujímavé vyšetreně neuropsychologické tomografie a děláče je to na dva dny. V srdce výsledky budou a zledem k tomu kolik mám léd a předpokladám, že ještě nejakých pár desítek let budu žít, budu mít možnost podívat. V srdce budou se podívat, jak se mlel na tom slediska dušemní schopnosti. V srdce budou se podívat, jaké to bude v 70-80. Kdybych měl takový gen, jak má otec, který oslávil 94 let před minulý týden, tak bych to měl na papíře a dokázal bych se podle toho jako řídit. Otec se neustále stěžuje, že ho bolí nohy, brzího, klouby a tak dále. Tato rozhduvící je to, že máte takzvané čistou hlavu, to znamenál netrpí ten nejakým Parkinsonem, Alzheimerem, demenci a další chorobami. To ostatné je dané věkem, který tělo se větší.
A12: COBEN_CZCOBEN013 | B12: 194 | C12: 131 | D12: 0.6752577319587629 | E12: 0.4896907216494845 | F12: 0.7557251908396947 | G12: 0.8802909164911273 | H12: 0.020618556701030927 | I12: 0.015463917525773196 | J12: 4 | K12: 3 | L12: 4 | M12: 0.5282051282051282 | N12: 103 | O12: 195 | P12: 6 | Q12: 32.333333333333336 | R12: 4.166666666666667 | S12: 25 | T12: 0 | U12: 0.0 | V12: V dnešní vánoce, nebo letošný, to už vlastně jsou londské vánoce, se moc nepovedli, protože nebyl žádný sních, vnočky byli sklamane, stihli udělá dělá dělá dělá sněhuláka. Pak jsme chtěli dna procházku pravidelnou na Silvestra do lesa, kde se schází spousta lidí i tisíce, tam si pěkně blahopřejí to nového rok. U zdraví se je to moc příjemné, ale letos, protože byla obleva, tak přišlo mnoho méně lidí, hodně lidí, když viděli to počas, si zůstali doma, ale přesto ti skálni tam přišli a šlapali jsme v blate, žádný les nebyl krásný bílej, ale já jsem to vydržala, ani jsem nespadla, kluzalo se to strašně. Dokonce vnočky ani nechtěli s nám jít, tak zostali doma a my staři jsme se tam vypravili. No, potom už to bylo jednoduchý, zase o půlnoci nikdo nebyl venku, si cese jsou se nějakým ten malý ochronstřoj udělal, ale na ulici nebylo ani živáčka, všichni byli zalezli. No, nový rok to jsme se rozhodli, že když jsme sami s dědou, že si uděláme pižamu ve nový rok, aby byla nějaká změna, voletne jsme si pustili koncert zvídně, pak jsme si dali pozdější obět a nový rok byl za námi.
A13: COBEN_CZCOBEN014 | B13: 165 | C13: 121 | D13: 0.7333333333333333 | E13: 0.3878787878787879 | F13: 0.8347107438016529 | G13: 0.887716381945141 | H13: 0.012121212121212121 | I13: 0.030303030303030304 | J13: 2 | K13: 5 | L13: 3 | M13: 0.5662650602409639 | N13: 94 | O13: 166 | P13: 8 | Q13: 20.625 | R13: 3.0 | S13: 24 | T13: 0 | U13: 0.0 | V13: Tak dobrý den, já se menuju Jana Bartíkova a mou největší radości jsou 4 vnoučata. Nejmenší vnouče bude mít zítra narozeniny, sejde se celá rodina a těším se, že si spolu. Popovídáme, budeme mít dord a už mám přichistané dárky pro Elišku. Když je to vlastně chvilkou předvánoucemi, tak je to taková generálka na vánouce, protože něco podobného se bude odehrávat 24. prosince, kdy bude všťad drý den. Abych zase řekla něco jiného a nejenom pohrát o Elišce, tak dnes jsem se probudila, kdy poďvele jsem se z okna viděla, jsem, že padá sníh, je něco málou nad nulou, tak už jsem měla obavy, že bude náledi, že se mě asi nepůjde dobře, ale protože jsem vycházela z domu ož po 10. hodině, tak do té doby už se počasí uklitnilo, v uvodovkách změnilo a teď dokonce světislu ničko. Vždycky mám ve zvyků chodit na schusky drív, protože nesnáším nedochvilnost, když někdo přijde pozdě, ať z jakýchkoliv důvodu ale většinou by měl přijít v čas.
... A34: COBEN_CZCOBEN039 | B34: 114 | C34: 89 | D34: 0.7807017543859649 | E34: 0.3333333333333333 | F34: 0.8539325842696629 | G34: 0.8854505862780699 | H34: 0.03508771929824561 | I34: 0.0 | J34: 4 | K34: 0 | L34: 1 | M34: 0.5175438596491229 | N34: 59 | O34: 114 | P34: 5 | Q34: 22.8 | R34: 3.0 | S34: 15 | T34: 0 | U34: 0.0 | V34: Ráno se mě nechtělo stávat, v běly jsme později, proto pak jsme se zřežili v záce. Naštěstí se podařilo to zvládnout na stanovený čas, takže všechno na konec dobře dopadl. Inak dá se říct, že je pěkný den v celku, takže pokud se nám bude dážit a skončíme brzí, tak si ho ještě budeme moc užívat, řekněme a spon celé odpoledne nebo na večer. Inak co bych dál k tomu mohl říct, nevím v podstatě, už mění zvelice ne napadá, ale doufám, že to všechno do vřed opadne, budíš, že se co nejde dížíš s tadym dostanem príč. To byl žert, jinak nic takového závažného, co by mě mě mělo hodit se tu neděje.
A35: COBEN_CZCOBEN040 | W35: NF | X35: NF | Y35: NF | Z35: NF | AA35: NF | AB35: NF | AC35: NF | AD35: NF | AE35: NF | AF35: NF | AG35: NF | AH35: NF | AI35: NF | AJ35: NF | AK35: NF | AL35: NF | AM35: NF | AN35: NF | AO35: NF | AP35: NF | AQ35: NF
A36: COBEN_CZCOBEN042 | B36: 124 | C36: 104 | D36: 0.8387096774193549 | E36: 0.2661290322580645 | F36: 0.875 | G36: 0.9279445335524367 | H36: 0.016129032258064516 | I36: 0.03225806451612903 | J36: 2 | K36: 4 | L36: 3 | M36: 0.56 | N36: 70 | O36: 125 | P36: 13 | Q36: 9.538461538461538 | R36: 1.1538461538461537 | S36: 15 | T36: 0 | U36: 0.0 | V36: V dneskě snídaní jsem neměl chleba ze sírem a čaj. V kobědu si dám zřejmě lýzoto sopurkou a nějakou poévku. Kvečeři potom asi nějaké oce nebo nějaký zelý salát. Zítra za mnou přijde výčka a přijde se mě pochlubit, jak dopadla na přijimačkách. Strašně by chybřála, aby se dostala na tu školou, kterou si vybrala. Druhá výčka ta zase bude dělat teď. Závělíš neskoušky na vysoké škole, tak tež i vůlu přát všechno lejlepší. Obleklu se při tom, jak slavnost měli, až pudl na její promoce. A vůdu ní dávat nějaký věci dar. Požtě pořád. Do mamám kotíčku, není se Berina. Je taková dlouho srsta, hodna, až na to, že všechno poškraby mám zničený nábytek. No ale mám ji prostě rád, tak bych neublížila.
A37: COBEN_CZCOBEN044 | B37: 113 | C37: 83 | D37: 0.7345132743362832 | E37: 0.415929203539823 | F37: 0.7951807228915663 | G37: 0.8627598588363428 | H37: 0.0 | I37: 0.0 | J37: 0 | K37: 0 | L37: 3 | M37: 0.5929203539823009 | N37: 67 | O37: 113 | P37: 12 | Q37: 9.416666666666666 | R37: 1.0 | S37: 12 | T37: 0 | U37: 0.0 | V37: v městečku Velké Bílovice, až do svých 19 let. Studovala jsem na gimnáziu a potom jsem se přihlásila na ekonomické hnádstavbu hodoníně. Podkava jsem vždycky moc správné spolužáky a spolužačky. Do dneska se scházíme, máme roční srazi a je to moc hezké. Všichni vždycky přijdou. Po ekonomické jsem ještě začala studovat vysokou ekonomickou v Praze. Byly tam vyníkající spolužáky, tak si s nimi se scházíme taky. Do dneska mám hodně bráce dát dohromady všetské srazi. K mým koníčkům patří příroda. Takže s kamarády a kamarádkami máme takovou skupinu, která chodí po všechny kopcích, horách. Takže jsme na vysočině prošli už moc a moc různých prohlídek zámku a všeho možného. A co se tíče?
A38: COBEN_CZCOBEN046 | B38: 205 | C38: 136 | D38: 0.6634146341463415 | E38: 0.5073170731707317 | F38: 0.7426470588235294 | G38: 0.8731688886167988 | H38: 0.02926829268292683 | I38: 0.01951219512195122 | J38: 6 | K38: 4 | L38: 3 | M38: 0.5365853658536586 | N38: 110 | O38: 205 | P38: 18 | Q38: 11.38888888888889 | R38: 1.6111111111111112 | S38: 29 | T38: 1 | U38: 0.6166875655230538 | V38: No tak dobrý den, já jsem už 45 roku zaměstnana a stávám každý den ránovo půlpate, chodím na 6 hodinu. Každý den mě vzbudí štyří ptáčci, mám doma štyry anulky. Jejich historii vám teďka asi trochu povykládám. Cerká ještě když byla trochu mlačší, chtěla furt nějaké zvýrátko, protože se mi nechtěla pořídit psa, tak jsme se dohodli, že pořídíme anulky. Chcela modrou anulku samce. Tak se taky stalo. Taťka její, taťka ji pořídil modrou anulku samce. Pod nějaké době zjistila, že se jí zdá, že ten jeden ptáček si je tam smutné, že by chtěla ještě jednoho. Tak si uzmystila, že by to chtělo samičku. Tak jsme pořídili žlutou samičku. No, cerká furt čekala, že teda je to samec a samička, že jednou dojde k tomu, že budou mít mladěátka. No, jak je bylo pro nás všecky překvapení, když modrý samec nám snesli štyri vejce. Ach, ejhle, zistili jsme, že máme dvě samice. Taťka mi zničil cerých hov. Tak potom jí jeden den volal, že nějaký souset mu volal, že tam u nich přiletil nějaký papoušek, že to bude asi anulka a má to modre ozoby, že to bude asi samec. Tak vzala bedinku a šla pro něho. A skutečně byl to samec. Do měsíce...
A39: COBEN_CZCOBEN047 | B39: 173 | C39: 117 | D39: 0.6763005780346821 | E39: 0.4508670520231214 | F39: 0.811965811965812 | G39: 0.8463668666521202 | H39: 0.04046242774566474 | I39: 0.011560693641618497 | J39: 7 | K39: 2 | L39: 3 | M39: 0.5433526011560693 | N39: 94 | O39: 173 | P39: 14 | Q39: 12.357142857142858 | R39: 1.3571428571428572 | S39: 19 | T39: 0 | U39: 0.0 | V39: Rád bych řekla něco o svých koničcích. V současné době se věnují Józe. K čemuž jsem se rozhodla, protože mám problémy z páteří. Dále jsem se zapsala na univerzitu 3. věku, protože mě velmi zajímá historie. A v minulosti mým největším koničkem bylo moje povolání. Pracuvala jsem jako očitelka na základní škole. Protože jsem učila na vesnici, tak jsem učila celou radu předmětu. Myslím si, že jsem měla velmi dobré vztahy ze svými žáky, protože mě navrhli do ankety o zlatého ámose, což mě samozřejmě velmi potěšilo. Vyučovala jsem hlavně biologii, těloci, vykchemii, potom i dějepis a končila jsem na prvním stupni, kde jsem zistila, že práce s těmi nejmenšími mě vyhovvala naprosto dokonale. Takže do důchodu jsem odcházela velmi těžce. Odcházela se mi skutečně velmi těžce, protože moje povoláni byl mým koníčkem a velmi se mě milvala. Samozřejmě, že mezíme koníčky patří i moje rodina, s kterou se pravidelně scházíme, máme velmi dobré. Vztahy jen mě vždycky mrzelo, že žádný z mých synů se nedál na učitelskou dráhu, že se vidali jiným.
A40: COBEN_CZCOBEN048 | B40: 129 | C40: 98 | D40: 0.7596899224806202 | E40: 0.3643410852713178 | F40: 0.8367346938775511 | G40: 0.8847956582204229 | H40: 0.03875968992248062 | I40: 0.0 | J40: 5 | K40: 0 | L40: 4 | M40: 0.5193798449612403 | N40: 67 | O40: 129 | P40: 7 | Q40: 18.428571428571427 | R40: 2.4285714285714284 | S40: 17 | T40: 0 | U40: 0.0 | V40: Dneska v noci jsem se moc nevyspala, protože mě čekala cesta dobrna do výzkumného ústavu na vyšetření. Před každou cestou jsem nervozní, tak tomu spaní jsem mu nedala. Cestu jsme zvládli dobře, protože nám počasí přálo, ani nepřešelo, dálnice byla suchá, dojeli jsme se na čas. Zajeli jsme až před budovu, kde mě manžel zanechal, a budovu už jsem šla navštívit sama. Na recepci jsem se ohlásila, pani recepční o mě věděla, řekla, že věrozumí pani magistru, která si pro mě v 9 hodin přijde. Tak se taky stalo a pak začal kolotoč vyšetřování, který je skoro půl třetí odpoledné a budeme za chvíličku končit. Jsem ráda, že už to mám za sebou, i když to nebylo nepříjemné, ale už se těším domů, takže v úterí jsem jedu znovu.
A41: COBEN_CZCOBEN049 | B41: 149 | C41: 91 | D41: 0.610738255033557 | E41: 0.5637583892617449 | F41: 0.7142857142857143 | G41: 0.8072713812572723 | H41: 0.0 | I41: 0.006711409395973154 | J41: 0 | K41: 1 | L41: 4 | M41: 0.5838926174496645 | N41: 87 | O41: 149 | P41: 12 | Q41: 12.416666666666666 | R41: 1.4166666666666667 | S41: 17 | T41: 0 | U41: 0.0 | V41: Dobrý den, menuj se Eva Kourová a mám 3 děti, dvě cery a jednoho syna. O cina mám dvě děti, dvě dnou čata, chlapce a děvče. Od cer mám, od cery mám jedné, mám dvě děvčatá a od druhé cery mám dva kluky. Ten nejstårší už má 20, ostatní mají 10, 3 a 4 roky. Menuj se Dorotka, Rozárka, Honza, Štěpán a Kryštov. Kluci chodí do 4. třídy, starší holčička chodí do 2. třídy a ta nejmlačí chodí do školky. Mají záliby takové, že chodí tancovat, jeden bnuk chodí lesd na skálu, na takuto lezeckou. Ten nejmlačí chodí na vysokou školu, rád šarmuje, chodí do šarmíšského kroušku. Také se mušila nějaké oblečení, tak myslím si, že jsem to líbí a také chodí do kroušku, kde chodí do skautu a dělá tam vedoucího. Jezí na tábory a kluci než si jezdí s ním, takže myslím si, že jsem to líbí.
A42: COBEN_CZCOBEN050 | B42: 107 | C42: 70 | D42: 0.6542056074766355 | E42: 0.45794392523364486 | F42: 0.8285714285714286 | G42: 0.770457135615402 | H42: 0.009345794392523364 | I42: 0.0 | J42: 1 | K42: 0 | L42: 4 | M42: 0.48598130841121495 | N42: 52 | O42: 107 | P42: 9 | Q42: 11.88888888888889 | R42: 1.8888888888888888 | S42: 17 | T42: 0 | U42: 0.0 | V42: Jsem správoval jedné dveře a pak jsem odešel za sýnem do obchodu. Tam jsem zal auto. Naložil jsem palety do auto a odvezli dom. Doma jsem to vytřídil, odvezl nahoru a poskládal na kopu. Ty, co jsou na spalení a ty ostatní jsem naložil, poskládal na sebe a opětově naložil na auto dodávku, které budou dneska odvážet k prodeji. Na dovolenou pojdeme asi příští měsic do Horovácka a doufám, že se trošku odpočineme a zapomeneme na všechny starostícou so kolem nás. Pak se vrátíme a život pokračuje, bude pokračovat pomalodál. Opakuje se to a je to na nic. A jinak to, den co denu, dejde, a pak.
A43: COBEN_CZCOBEN052 | B43: 167 | C43: 123 | D43: 0.7365269461077845 | E43: 0.40119760479041916 | F43: 0.8130081300813008 | G43: 0.9016461798179752 | H43: 0.005988023952095809 | I43: 0.023952095808383235 | J43: 1 | K43: 4 | L43: 4 | M43: 0.6287425149700598 | N43: 105 | O43: 167 | P43: 12 | Q43: 13.916666666666666 | R43: 2.1666666666666665 | S43: 26 | T43: 0 | U43: 0.0 | V43: Tak mým dlouholetím koničkem je chvání psu. Máme doma psa kněrača malého černostří vžitého. Měli jsme jich i víc, ale v této době už potom jako přistády a pomalo odcházli, tak nám teďka zbyl už potom tedy jeden poslední. Svoutop si velice hraví. Manželka chodila na tvíčení, na aglity, na závody, kde jsme jezdili pod celé cestské republice po závodech a získávali nebo nezískávali nějaké místa na umístění nabedně. To znamená do třetího místa. Dovezli jsme si spoustu diplomů a medaili. Soužití se s těmi dobří je velice milé, jsou hrozně hraví, jsou vděční za každou radozd. Samozřejmě, člověk, když stárne, tak je už o mozené tím, že nemůže tak často chodit vjen jako drív. I tak se psi jsme pořád jako velice dobrí přátelé. Dá se říct, že soužití se psi přináší, jak tomu psou i tím chovatelům spoustu hradosti. V naše děti mají taky psi, znamená vzalistí z útru kupca, které je podstatně většiněště náš, ale je už vychovaný chodil noc věčák a velice poslušné.
A44: COBEN_CZCOBEN053 | B44: 188 | C44: 131 | D44: 0.6968085106382979 | E44: 0.44148936170212766 | F44: 0.8015267175572519 | G44: 0.8757520776428601 | H44: 0.0 | I44: 0.015957446808510637 | J44: 0 | K44: 3 | L44: 2 | M44: 0.5561497326203209 | N44: 104 | O44: 187 | P44: 13 | Q44: 14.461538461538462 | R44: 1.2307692307692308 | S44: 16 | T44: 0 | U44: 0.0 | V44: Znávěl jsem všem z těch dnes to pohovořit o formale a úspějších našeho národního týmu. V roce 34. jiveli ve finále Mistrovský svět a v Itálii, bo už a prohráli po volice neserieľ s ním způsobu v soucování. Po druhé se jim to podařilo v roce 62. v Čile, kdy postoupili do finále. Tam prohráli z Brasilii 3.1. Bylo to nešťastné úzkání, protože v Bershladecí znali ty místní poměry, věděl jak svítí slunce a kdy bude svítit do očí našeho brantáři, což se tady naplnilo a takhle pustilo 3 do haly. Potom další takové slavné výročí v našich formalistů, bylo v roce 76. Kdy se probojivali do finále Mistrovské Evropy, Vyduoslávy, to intérát vytrát zali remizovat s Německém a rozhodlící, potom byli penálty. Na penálti naši zvítězali 1-0, tam padla slavna penálta, když si vysřelvalo do prostředbrány a měl s ty brantář, kto nečekal, hnul se na jednu stranu. O té robí už na té vlate slavné úspěchy nástavy, s natěžtě v Portugalskou, to byl náš tým optimální formě. Tam hrali takový hráči, a totohle, baroš, podobně, a nedvět a takové hvězdí už jeď si neváme.
A45: COBEN_CZCOBEN054 | B45: 136 | C45: 103 | D45: 0.7573529411764706 | E45: 0.36764705882352944 | F45: 0.8349514563106796 | G45: 0.8791669148104492 | H45: 0.04411764705882353 | I45: 0.014705882352941176 | J45: 6 | K45: 2 | L45: 4 | M45: 0.5401459854014599 | N45: 74 | O45: 137 | P45: 10 | Q45: 13.6 | R45: 1.9 | S45: 19 | T45: 0 | U45: 0.0 | V45: Minulou neděli nás pozvali přátle do valče na prohlídku zámku. Zámek je pěkný, byl zcela zdevastován, ale velkou píli mají celé pana Vali a jeho manželky. Byl zámek opraven a přistaveno k němu, ještě další křídlo. To je hotel a velnes. Byl hezky den, přijeli jsme a o tej manželka mě dovezla až do areálu vádečského zámku. Všetíli jsme se z námí, kteří nás zali na procházku parkem, abychom si celý a real mohli prohlédnou. A pak jsme posedili v družném hovoru. Po obědě z nám i a manželka šli na prohlídku zámku. Já jsem tohle dmítle, protože to pro mě bylo přilišná ročné. A tak jsem seděl v takové klité věrandě a tam pozoroval, jak lidé hosté kolem do kolá chodí a věnují se v plavání v teplé vodě, ve vyřivce a nebo jen chvůzi.
A46: COBEN_CZCOBEN055 | B46: 188 | C46: 128 | D46: 0.6808510638297872 | E46: 0.48404255319148937 | F46: 0.7578125 | G46: 0.8819830340542403 | H46: 0.010638297872340425 | I46: 0.026595744680851064 | J46: 2 | K46: 5 | L46: 4 | M46: 0.4789473684210526 | N46: 91 | O46: 190 | P46: 10 | Q46: 18.8 | R46: 2.5 | S46: 25 | T46: 0 | U46: 0.0 | V46: Takže dnes kanáno jsem všet z hodin vezala manžela do práce, protože jsem potřeba auto a jela jsem k synový hlída do mnučky, protože měl nějaké potřeba něco vyhrídit. Asi v jeden áz hodin jsem přijela domu a zjistila jsem, že máme mravence, takže jsem musela jít na 14-13 na vyšitření, takže jsem si říkala, že třeba v druhé ryj si koupím ty domečky pro tím ravencem. Což jsem udělala, vyšlo mě to tak jako rád, abych přišla tady na čas, hvěličku jsem čekala, nejvíc pro mě přišla paník se, ktorou bych měla teď spou pracovat. Ovidíme, jak to bude všechno dá po kračovat, se dozvím, co a jak, doufám, že to nebudem žádnou pro planove. Ještě bych můj hrít něco, takže čekám, co bude dál. Dnes je to poslední vyšetření, měl bych to by dási dvě hodiny. Potom, kdyby budu vědění nějaké vysledky a budu k planí profesorce, až na to, kdy mám dálší návštěvoutoznam, na včervnu, která by mimožná řeká něco dál. Ještě něco. Už mětě nic nenapadá, takže svedím tady v nějaké misnosti, kde jsou zálene skřínky. Je tady mikrofon, na které se náhravat.
A47: COBEN_CZCOBEN057 | B47: 163 | C47: 122 | D47: 0.7484662576687117 | E47: 0.3987730061349693 | F47: 0.8032786885245902 | G47: 0.906171661388369 | H47: 0.018404907975460124 | I47: 0.018404907975460124 | J47: 3 | K47: 3 | L47: 4 | M47: 0.6463414634146342 | N47: 106 | O47: 164 | P47: 19 | Q47: 8.578947368421053 | R47: 0.6842105263157895 | S47: 13 | T47: 0 | U47: 0.0 | V47: Ménuj se Eva Palátová, máman řela Jaroslava a dvě děti. Alež má dvě vnučky. Martu máme do mama invalidní důchod. Děti často hlídám. Adelka chodí do první třídí. Elinka má čtěři roky a teď byla dlouhodobě nemocná, takže se mý pořád měla u nás doma. Často hrajeme různé hry. Má nejradějí pohádky, takže jí čtu. Adelka zase je víc založena sportovně, takže by nejradějí běhala, skákala, cvičila. Do cvičení chodím i s manželem pro starší generaci. Zučastnili jsme se i v Praze na sletu. Inak chodíme každý čtvrtek. Máme takový pěkný kolektív, kde si posedíme, pobavíme se. Když má někdo narození, něco dobrého přinese. Zasmějeme se. Manžel si teď našel brigádu na čtěři hodiny, takže chodí dělá správce na DPSC u nás tam ve středicích. Inak máme dvorek za hradu, takže už se těšíme teď na jaro, až přijde pěkné počasí, aby jsme mohli vyrazit do zahrátky. Pěstujeme veškerou zeleninu pro sebe, ovocné stromky tam máme. To malé množství nás to prostě baví.
